Workbook

Sheet sueldos
A1: QN | B1: MES | C1: MES NO. | D1: NOMBRE | E1: Total sueldo (N) | F1: Total prestaciones (N) | G1: Total cuotas patrón (N) | H1: vales 1 (N) | I1: vales 2 (N) | J1: Puntualidad (lira) | K1: Excedente (lira) | L1: Comisión (lira) | M1: Provisiones | N1: Praxx | O1: NOMBRE BIEN | P1: Total | Q1: PROVISION | R1: TOTAL2 | S1: Departamento
A2: 1 | B2: agosto | C2: 8 | D2: RUIZ ZARATE GAEL | E2: 5115 | F2: 1023 | G2: 7753.72 | H2: 300 | J2: 800 | K2: 5657.22 | L2: 258.29 | O2: RUIZ ZARATE GAEL | P2: 20907.23 | R2: 20907.23 | S2: Estafeta
A3: 1 | B3: agosto | C3: 8 | D3: LOPEZ HERNANDEZ RAUL IVAN | E3: 5616.6 | F3: 1404.15 | G3: 8776.25 | H3: 200 | J3: 560 | K3: 1086.32 | L3: 65.85 | O3: LOPEZ HERNANDEZ RAUL IVAN | P3: 17709.17 | R3: 17709.17 | S3: TAP/IMILE
A4: 1 | B4: agosto | C4: 8 | D4: RUBIO MACIAS CARLOS ANDRES | E4: 7077.15 | F4: 1415.43 | G4: 10613.46 | H4: 350 | J4: 2000 | K4: 5003.81 | L4: 280.15 | O4: RUBIO MACIAS CARLOS ANDRES | P4: 26740 | R4: 26740 | S4: Staff
A5: 1 | B5: agosto | C5: 8 | D5: JUAREZ SANDOVAL ROCIO | E5: 4725.6 | F5: 2677.84 | G5: 8900.92 | H5: 350 | J5: 800 | K5: 6706.79 | L5: 300.27 | O5: JUAREZ SANDOVAL ROCIO | P5: 24461.42 | R5: 24461.42 | S5: Staff
A6: 1 | B6: agosto | C6: 8 | D6: MEDINA SANCHEZ LUIS | E6: 5979 | F6: 1195.8 | G6: 8957.99 | H6: 200 | J6: 800 | K6: 3077.21 | L6: 155.09 | O6: MEDINA SANCHEZ LUIS | P6: 20365.09 | R6: 20365.09 | S6: Staff
A7: 1 | B7: agosto | C7: 8 | D7: ZUÑIGA GONZALEZ EMMANUEL | E7: 4725.6 | F7: 945.12 | G7: 7116.22 | H7: 200 | J7: 1320 | K7: 5733.1 | L7: 282.12 | O7: ZUÑIGA GONZALEZ EMMANUEL | P7: 20322.16 | R7: 20322.16 | S7: Staff
A8: 1 | B8: agosto | C8: 8 | D8: CAMARGO CASTRO BEATRIZ SELENE | E8: 5017.05 | F8: 997.41 | G8: 7524.08 | H8: 300 | K8: 0 | L8: 0 | O8: CAMARGO CASTRO BEATRIZ SELENE | P8: 13838.54 | R8: 13838.54 | S8: Staff
A9: 1 | B9: agosto | C9: 8 | D9: MUÑOZ SEGURA KARINA | E9: 3780.48 | F9: 2362.8 | G9: 7600.62 | H9: 200 | I9: 378.05 | K9: 0 | L9: 0 | O9: MUÑOZ SEGURA KARINA | P9: 14321.95 | R9: 14321.95 | S9: Staff
A10: 1 | B10: agosto | C10: 8 | D10: PEREZ RIOS WILLIAMS ALEXANDER | E10: 3361.5 | F10: 4407.3 | G10: 9469.07 | H10: 300 | J10: 520 | K10: 1121.33 | L10: 65.65 | O10: PEREZ RIOS WILLIAMS ALEXANDER | P10: 19244.85 | R10: 19244.85 | S10: Staff
A11: 1 | B11: agosto | C11: 8 | D11: ALEMAN LOPEZ LUIS ALBERTO | E11: 5115 | F11: 1023 | G11: 7692.34 | H11: 350 | J11: 800 | K11: 4487.22 | L11: 211.49 | O11: ALEMAN LOPEZ LUIS ALBERTO | P11: 19679.05 | R11: 19679.05 | S11: Veracruz
A12: 1 | B12: agosto | C12: 8 | D12: ROSAS LOBERA PATRICIA | E12: 4725.6 | F12: - | G12: 6450.8 | K12: 0 | L12: 0 | O12: ROSAS LOBERA PATRICIA | P12: 11176.4 | R12: 11176.4 | S12: Amazon 1
A13: 1 | B13: agosto | C13: 8 | D13: PEREZ LAGUNAS WENDY PAOLA | E13: 5115 | F13: 1023 | G13: 7753.72 | H13: 300 | J13: 600 | K13: 1987.22 | L13: 103.49 | O13: PEREZ LAGUNAS WENDY PAOLA | P13: 16882.43 | R13: 16882.43 | S13: Toluca
A14: 1 | B14: agosto | C14: 8 | D14: GARCIA BECERRIL YARASKA YETZEL | E14: 4491.48 | F14: 2221.17 | G14: 8382.14 | H14: 300 | I14: 480 | K14: 0 | L14: 0 | O14: GARCIA BECERRIL YARASKA YETZEL | P14: 15874.79 | R14: 15874.79 | S14: Staff
A15: 1 | B15: agosto | C15: 8 | D15: RENDON MORALES MANUEL ALEJANDRO | E15: 4725.6 | F15: 945.12 | G15: 7172.92 | H15: 350 | J15: 800 | K15: 4772.84 | L15: 222.91 | O15: RENDON MORALES MANUEL ALEJANDRO | P15: 18989.39 | R15: 18989.39 | S15: Staff
A16: 1 | B16: agosto | C16: 8 | D16: ARRIAGA ROSAS CADERIN | E16: 4725.6 | F16: 945.12 | G16: 7168.18 | H16: 300 | J16: 480 | K16: 772.84 | L16: 50.11 | O16: ARRIAGA ROSAS CADERIN | P16: 14441.85 | R16: 14441.85 | S16: Toluca
A17: 1 | B17: agosto | C17: 8 | D17: MORA ARROYO MARIA ELBA | E17: 4985.11 | F17: 1763.96 | G17: 8454.42 | H17: 200 | J17: 1200 | K17: 7768.29 | L17: 358.73 | O17: MORA ARROYO MARIA ELBA | P17: 24730.51 | R17: 24730.51 | S17: Staff
A18: 1 | B18: agosto | C18: 8 | D18: AGUERO GONZALEZ JUAN CARLOS | E18: 4725.6 | F18: 1181.4 | G18: 7418.65 | H18: 350 | J18: 600 | K18: 2424.25 | L18: 120.97 | O18: AGUERO GONZALEZ JUAN CARLOS | P18: 16820.87 | R18: 16820.87 | S18: TAP/IMILE
A19: 1 | B19: agosto | C19: 8 | D19: ACACIO LARA MANUEL | E19: 5753.85 | F19: 3068.72 | G19: 10677.14 | H19: 300 | J19: 760 | K19: 4609.35 | L19: 214.77 | O19: ACACIO LARA MANUEL | P19: 25383.83 | R19: 25383.83 | S19: staff
A20: 1 | B20: agosto | C20: 8 | D20: ARELLANO HERNANDEZ OLGA LIDIA | E20: 5753.85 | F20: 990.77 | G20: 8516.07 | H20: 350 | J20: 640 | K20: 1994.11 | L20: 105.36 | O20: ARELLANO HERNANDEZ OLGA LIDIA | P20: 18350.16 | R20: 18350.16 | S20: imile aifa
A21: 1 | B21: agosto | C21: 8 | D21: ROJAS MORALES ANASTACIO | E21: 4492.56 | F21: 1377.62 | G21: 7577.92 | H21: 300 | J21: 420 | K21: 0 | L21: 16.8 | O21: ROJAS MORALES ANASTACIO | P21: 14184.9 | R21: 14184.9 | S21: Toluca
A22: 1 | B22: agosto | C22: 8 | D22: GARCIA GONZALEZ WENDY GUADALUPE | E22: 5017.05 | F22: 1003.41 | G22: 7591.73 | H22: 300 | J22: 480 | K22: 588.78 | L22: 42.75 | O22: GARCIA GONZALEZ WENDY GUADALUPE | P22: 15023.72 | R22: 15023.72 | S22: Toluca
A23: 1 | B23: agosto | C23: 8 | D23: ARANDA MARTINEZ JOSE RAUL | E23: 3051 | F23: 2644.2 | G23: 7286.96 | H23: 300 | J23: 480 | K23: 879.32 | L23: 54.37 | O23: ARANDA MARTINEZ JOSE RAUL | P23: 14695.85 | R23: 14695.85 | S23: Toluca
A24: 1 | B24: agosto | C24: 8 | D24: COLIN MORALES ARMANDO | E24: 7152.6 | F24: 1788.15 | G24: 11570.55 | H24: 300 | J24: 652 | K24: 430.69 | L24: 43.31 | O24: COLIN MORALES ARMANDO | P24: 21937.3 | R24: 21937.3 | S24: Staff
A25: 1 | B25: agosto | C25: 8 | D25: CAMPOS ROMERO CRISTINA | E25: 4682.58 | F25: 1270.99 | G25: 7520.9 | H25: 300 | J25: 480 | K25: 647.95 | L25: 45.12 | O25: CAMPOS ROMERO CRISTINA | P25: 14947.54 | R25: 14947.54 | S25: Staff
A26: 1 | B26: agosto | C26: 8 | D26: GONZALEZ ROJAS EDUARDO | E26: 3361.59 | F26: 2913.38 | G26: 7994.75 | H26: 200 | J26: 520 | K26: 882.08 | L26: 56.08 | O26: GONZALEZ ROJAS EDUARDO | P26: 15927.88 | R26: 15927.88 | S26: Toluca
A27: 1 | B27: agosto | C27: 8 | D27: ALBAVERA LAGUNAS JORGE | E27: 4410.98 | F27: 1076.03 | G27: 6979.62 | H27: 300 | K27: 886.7 | L27: 35.47 | O27: ALBAVERA LAGUNAS JORGE | P27: 13688.8 | R27: 13688.8 | S27: imile aifa
A28: 1 | B28: agosto | C28: 8 | D28: CORTES ZEPEDA RENE | E28: 4445.52 | F28: 1985.71 | G28: 8150.72 | H28: 350 | J28: 880 | K28: 16449.64 | L28: 693.19 | O28: CORTES ZEPEDA RENE | P28: 32954.78 | R28: 32954.78 | S28: Estafeta
A29: 1 | B29: agosto | C29: 8 | D29: HERRERA MONDRAGON ZUREYMA DENYSSE | E29: 5026.8 | F29: 705.36 | G29: 7291.26 | H29: 300 | J29: 460 | K29: 500 | L29: 38.4 | O29: HERRERA MONDRAGON ZUREYMA DENYSSE | P29: 14321.82 | R29: 14321.82 | S29: Staff
A30: 1 | B30: agosto | C30: 8 | D30: GARCIA BRISEÑO DARIO ABRAHAM | E30: 4725.6 | F30: 945.12 | G30: 7172.92 | H30: 350 | J30: 880 | K30: 3332.27 | L30: 168.49 | O30: GARCIA BRISEÑO DARIO ABRAHAM | P30: 17574.4 | R30: 17574.4 | S30: Toluca
A31: 1 | B31: agosto | C31: 8 | D31: FLORES GARCIA SOFIA | E31: 4347.2 | F31: 1538.24 | G31: 7448.5 | H31: 300 | J31: 540 | K31: 1458.18 | L31: 79.93 | O31: FLORES GARCIA SOFIA | P31: 15712.05 | R31: 15712.05 | S31: STAFF
A32: 1 | B32: agosto | C32: 8 | D32: MENDOZA CASIMIRO PAULA | E32: 4725.6 | F32: - | G32: 6186.46 | H32: 200 | I32: 378.05 | K32: 0 | L32: 0 | O32: MENDOZA CASIMIRO PAULA | P32: 11490.11 | R32: 11490.11 | S32: Toluca
A33: 1 | B33: agosto | C33: 8 | D33: RAMIREZ MUÑOZ LETICIA | E33: 0 | F33: - | G33: - | H33: - | K33: 0 | L33: 0 | O33: RAMIREZ MUÑOZ LETICIA | P33: 0 | R33: 0 | S33: Staff
A34: 1 | B34: agosto | C34: 8 | D34: SANCHEZ GONZALEZ BRIAN ALEXIS | E34: 4725.6 | F34: 390.94 | G34: 6541.87 | H34: 300 | K34: 0 | L34: 0 | O34: SANCHEZ GONZALEZ BRIAN ALEXIS | P34: 11958.41 | R34: 11958.41 | S34: Staff
A35: 1 | B35: agosto | C35: 8 | D35: MARTINEZ DEL RIO EDUARDO ALEXEI | E35: 5016.9 | F35: 703.38 | G35: 7274.43 | H35: 300 | J35: 520 | K35: 325 | L35: 33.8 | O35: MARTINEZ DEL RIO EDUARDO ALEXEI | P35: 14173.51 | R35: 14173.51 | S35: Staff
A36: 1 | B36: agosto | C36: 8 | D36: GARCIA OCAMPO JAZMIN | E36: 5616.3 | F36: 1123.26 | G36: 8483.75 | H36: 300 | J36: 620 | K36: 1745.27 | L36: 94.61 | O36: GARCIA OCAMPO JAZMIN | P36: 17983.19 | R36: 17983.19 | S36: laredo
A37: 1 | B37: agosto | C37: 8 | D37: MONROY CAMPOS JOSE ANGEL | E37: 5015.85 | F37: 733.17 | G37: 7306.59 | H37: 300 | J37: 480 | K37: 879.22 | L37: 54.37 | O37: MONROY CAMPOS JOSE ANGEL | P37: 14769.2 | R37: 14769.2 | S37: Toluca
A38: 1 | B38: agosto | C38: 8 | D38: CHAVEZ AGUILAR LORENA | E38: 4725.6 | F38: 512 | G38: 6717.73 | H38: 300 | J38: 480 | K38: 1000 | L38: 59.2 | O38: CHAVEZ AGUILAR LORENA | P38: 13794.53 | R38: 13794.53 | S38: Toluca
A39: 1 | B39: agosto | C39: 8 | D39: HERNANDEZ AGUILAR ANGELICA CELINA | E39: 7077 | F39: 1415.4 | G39: 10698.17 | H39: 350 | J39: 2496 | K39: 11850 | L39: 573.84 | O39: HERNANDEZ AGUILAR ANGELICA CELINA | P39: 17230.205 | Q39: 0 | R39: 17230.205 | S39: estafeta
D40: HERNANDEZ AGUILAR ANGELICA CELINA | O40: HERNANDEZ AGUILAR ANGELICA CELINA | P40: 17230.205 | Q40: 0 | R40: 17230.205 | S40: imile aifa
...

Sheet emitidas
A1: TipoCambio | B1: Moneda | C1: ReceptorNombre | D1: Descripcion | E1: Importe | F1: DescuentoConcepto | G1: REFERENCIA | H1: ADUANA | I1: CC | J1: TIPO | K1: MONTO
B2: MXN | C2: PROMINENT FLUID CONTROLS DE MEXICO | D2: TRANSPORTE | E2: 4150 | F2: 0 | G2: JMA6000224 | H2: TRANSITO | I2: {=INDEX(CC!C:C,MATCH(1,(CC!A:A=H2)*(CC!B:B=J2),0))} -> 602 | J2: PROPIOS | K2: 4150
B3: MXN | C3: CIPSA INDUSTRIAS | D3: CAPTURA DE VUCEM | E3: 339.06 | F3: 0 | G3: JIT6111043 | H3: TOLUCA | I3: {=INDEX(CC!C:C,MATCH(1,(CC!A:A=H3)*(CC!B:B=J3),0))} -> 1002 | J3: PROPIOS | K3: 339.06
C4: CIPSA INDUSTRIAS | D4: MANIFESTACION DE VALOR | E4: 1500 | F4: 0 | G4: JIT6111043 | H4: TOLUCA | I4: {=INDEX(CC!C:C,MATCH(1,(CC!A:A=H4)*(CC!B:B=J4),0))} -> 1002 | J4: PROPIOS | K4: 1500
C5: CIPSA INDUSTRIAS | D5: MANIOBRAS AA | E5: 4305.53 | F5: 0 | G5: JIT6111043 | H5: TOLUCA | I5: {=INDEX(CC!C:C,MATCH(1,(CC!A:A=H5)*(CC!B:B=J5),0))} -> 1002 | J5: PROPIOS | K5: 4305.53
C6: CIPSA INDUSTRIAS | D6: CONTRAPRESTACIÓN | E6: 36.29 | F6: 0 | G6: JIT6111043 | H6: TOLUCA | I6: {=INDEX(CC!C:C,MATCH(1,(CC!A:A=H6)*(CC!B:B=J6),0))} -> 1002 | J6: PROPIOS | K6: 36.29
C7: CIPSA INDUSTRIAS | D7: ASESORIA ADUANAL | E7: 4666.05 | F7: 0 | G7: JIT6111043 | H7: TOLUCA | I7: {=INDEX(CC!C:C,MATCH(1,(CC!A:A=H7)*(CC!B:B=J7),0))} -> 1002 | J7: PROPIOS | K7: 4666.05
B8: MXN | C8: JARB Y ASOCIADOS | D8: MANIFESTACION DE VALOR | E8: 1000 | F8: 0 | G8: ARA6000161 | H8: AIFA | I8: {=INDEX(CC!C:C,MATCH(1,(CC!A:A=H8)*(CC!B:B=J8),0))} -> 902 | J8: PROPIOS | K8: 1000
C9: JARB Y ASOCIADOS | D9: CONTRAPRESTACIÓN | E9: 30 | F9: 0 | G9: ARA6000161 | H9: AIFA | I9: {=INDEX(CC!C:C,MATCH(1,(CC!A:A=H9)*(CC!B:B=J9),0))} -> 902 | J9: PROPIOS | K9: 30
B10: MXN | C10: B. BRAUN MEDICAL DE MEXICO | D10: TRANSPORTE | E10: 4600 | F10: 0 | G10: JMA6000219 | H10: TRANSITO | I10: {=INDEX(CC!C:C,MATCH(1,(CC!A:A=H10)*(CC!B:B=J10),0))} -> 602 | J10: PROPIOS | K10: 4600
B11: MXN | C11: EDITORIAL PANINI MEXICO | D11: CAPTURA DE VUCEM | E11: 324.5 | F11: 0 | G11: JMA6000209 | H11: CDMX | I11: {=INDEX(CC!C:C,MATCH(1,(CC!A:A=H11)*(CC!B:B=J11),0))} -> 1502 | J11: PROPIOS | K11: 324.5
C12: EDITORIAL PANINI MEXICO | D12: SERVICIOS COMPLEMENTARIOS | E12: 3461.42 | F12: 0 | G12: JMA6000209 | H12: CDMX | I12: {=INDEX(CC!C:C,MATCH(1,(CC!A:A=H12)*(CC!B:B=J12),0))} -> 1502 | J12: PROPIOS | K12: 3461.42
C13: EDITORIAL PANINI MEXICO | D13: CONTRAPRESTACIÓN | E13: 32.44 | F13: 0 | G13: JMA6000209 | H13: CDMX | I13: {=INDEX(CC!C:C,MATCH(1,(CC!A:A=H13)*(CC!B:B=J13),0))} -> 1502 | J13: PROPIOS | K13: 32.44
C14: EDITORIAL PANINI MEXICO | D14: ASESORIA ADUANAL | E14: 4597.2 | F14: 0 | G14: JMA6000209 | H14: CDMX | I14: {=INDEX(CC!C:C,MATCH(1,(CC!A:A=H14)*(CC!B:B=J14),0))} -> 1502 | J14: PROPIOS | K14: 4597.2
A15: 17.3288 | B15: USD | C15: IMILE DELIVERY SERVICES MEXICO | D15: SERVICIO DE MANIOBRA | E15: 22880 | F15: 0 | G15: IMILE JULIO 1 | H15: IMILE AIFA | I15: {=INDEX(CC!C:C,MATCH(1,(CC!A:A=H15)*(CC!B:B=J15),0))} -> 1402 | J15: PROPIOS | K15: =(E15-F15)*$A$15 -> 396482.94
C16: IMILE DELIVERY SERVICES MEXICO | D16: RECONOCIMIENTO ADUANERO | E16: 5130 | F16: 0 | G16: IMILE JULIO 1 | H16: IMILE AIFA | I16: {=INDEX(CC!C:C,MATCH(1,(CC!A:A=H16)*(CC!B:B=J16),0))} -> 1402 | J16: PROPIOS | K16: =(E16-F16)*$A$15 -> 88896.744
C17: IMILE DELIVERY SERVICES MEXICO | D17: CANDADOS | E17: 1090 | F17: 0 | G17: IMILE JULIO 1 | H17: IMILE AIFA | I17: {=INDEX(CC!C:C,MATCH(1,(CC!A:A=H17)*(CC!B:B=J17),0))} -> 1402 | J17: PROPIOS | K17: =(E17-F17)*$A$15 -> 18888.392
B18: MXN | C18: CARGOTECNIA EQUIPOS | D18: COORDINACION DE EMBARQUE | E18: 1695.33 | F18: 0 | G18: JMA6000204 | H18: CDMX | I18: {=INDEX(CC!C:C,MATCH(1,(CC!A:A=H18)*(CC!B:B=J18),0))} -> 1502 | J18: PROPIOS | K18: 1695.33
C19: CARGOTECNIA EQUIPOS | D19: SERVICIOS COMPLEMENTARIOS | E19: 2797.05 | F19: 0 | G19: JMA6000204 | H19: CDMX | I19: {=INDEX(CC!C:C,MATCH(1,(CC!A:A=H19)*(CC!B:B=J19),0))} -> 1502 | J19: PROPIOS | K19: 2797.05
C20: CARGOTECNIA EQUIPOS | D20: MANIOBRAS AA | E20: 14348.31 | F20: 0 | G20: JMA6000204 | H20: CDMX | I20: {=INDEX(CC!C:C,MATCH(1,(CC!A:A=H20)*(CC!B:B=J20),0))} -> 1503 | J20: TERCEROS | K20: 14348.31
C21: CARGOTECNIA EQUIPOS | D21: PREVIO AA | E21: 1488 | F21: 0 | G21: JMA6000204 | H21: CDMX | I21: {=INDEX(CC!C:C,MATCH(1,(CC!A:A=H21)*(CC!B:B=J21),0))} -> 1503 | J21: TERCEROS | K21: 1488
C22: CARGOTECNIA EQUIPOS | D22: REVALIDACION AA | E22: 2835 | F22: 0 | G22: JMA6000204 | H22: CDMX | I22: {=INDEX(CC!C:C,MATCH(1,(CC!A:A=H22)*(CC!B:B=J22),0))} -> 1503 | J22: TERCEROS | K22: 2835
C23: CARGOTECNIA EQUIPOS | D23: CONTRAPRESTACIÓN | E23: 35 | F23: 0 | G23: JMA6000204 | H23: CDMX | I23: {=INDEX(CC!C:C,MATCH(1,(CC!A:A=H23)*(CC!B:B=J23),0))} -> 1502 | J23: PROPIOS | K23: 35
C24: CARGOTECNIA EQUIPOS | D24: ASESORIA ADUANAL | E24: 1468.45 | F24: 0 | G24: JMA6000204 | H24: CDMX | I24: {=INDEX(CC!C:C,MATCH(1,(CC!A:A=H24)*(CC!B:B=J24),0))} -> 1502 | J24: PROPIOS | K24: 1468.45
B25: MXN | C25: EQUIPOS ESPECIALES MPOWER | D25: COORDINACION DE EMBARQUE | E25: 1555.35 | F25: 0 | G25: LAI2602712 | H25: LAZARO | I25: {=INDEX(CC!C:C,MATCH(1,(CC!A:A=H25)*(CC!B:B=J25),0))} -> 1102 | J25: PROPIOS | K25: 1555.35
C26: EQUIPOS ESPECIALES MPOWER | D26: CAPTURA DE VUCEM | E26: 339.06 | F26: 0 | G26: LAI2602712 | H26: LAZARO | I26: {=INDEX(CC!C:C,MATCH(1,(CC!A:A=H26)*(CC!B:B=J26),0))} -> 1102 | J26: PROPIOS | K26: 339.06
C27: EQUIPOS ESPECIALES MPOWER | D27: MANIOBRAS AA | E27: 9563.79 | F27: 0 | G27: LAI2602712 | H27: LAZARO | I27: {=INDEX(CC!C:C,MATCH(1,(CC!A:A=H27)*(CC!B:B=J27),0))} -> 1103 | J27: TERCEROS | K27: 9563.79
C28: EQUIPOS ESPECIALES MPOWER | D28: CONTRAPRESTACIÓN | E28: 36.29 | F28: 0 | G28: LAI2602712 | H28: LAZARO | I28: {=INDEX(CC!C:C,MATCH(1,(CC!A:A=H28)*(CC!B:B=J28),0))} -> 1102 | J28: PROPIOS | K28: 36.29
C29: EQUIPOS ESPECIALES MPOWER | D29: ASESORIA ADUANAL | E29: 7123.5 | F29: 0 | G29: LAI2602712 | H29: LAZARO | I29: {=INDEX(CC!C:C,MATCH(1,(CC!A:A=H29)*(CC!B:B=J29),0))} -> 1102 | J29: PROPIOS | K29: 7123.5
C30: EQUIPOS ESPECIALES MPOWER | D30: ENTREGA DE LLENADO Y VACIO AA | E30: 3000 | F30: 0 | G30: LAI2602712 | H30: LAZARO | I30: {=INDEX(CC!C:C,MATCH(1,(CC!A:A=H30)*(CC!B:B=J30),0))} -> 1103 | J30: TERCEROS | K30: 3000
B31: MXN | C31: PROMINENT FLUID CONTROLS DE MEXICO | D31: COORDINACION DE EMBARQUE | E31: 945.65 | F31: 0 | G31: JMA6000225 | H31: CDMX | I31: {=INDEX(CC!C:C,MATCH(1,(CC!A:A=H31)*(CC!B:B=J31),0))} -> 1502 | J31: PROPIOS | K31: 945.65
C32: PROMINENT FLUID CONTROLS DE MEXICO | D32: CAPTURA DE VUCEM | E32: 362.91 | F32: 0 | G32: JMA6000225 | H32: CDMX | I32: {=INDEX(CC!C:C,MATCH(1,(CC!A:A=H32)*(CC!B:B=J32),0))} -> 1502 | J32: PROPIOS | K32: 362.91
C33: PROMINENT FLUID CONTROLS DE MEXICO | D33: SERVICIOS COMPLEMENTARIOS | E33: 1536.68 | F33: 0 | G33: JMA6000225 | H33: CDMX | I33: {=INDEX(CC!C:C,MATCH(1,(CC!A:A=H33)*(CC!B:B=J33),0))} -> 1502 | J33: PROPIOS | K33: 1536.68
C34: PROMINENT FLUID CONTROLS DE MEXICO | D34: MANIFESTACION DE VALOR | E34: 1500 | F34: 0 | G34: JMA6000225 | H34: CDMX | I34: {=INDEX(CC!C:C,MATCH(1,(CC!A:A=H34)*(CC!B:B=J34),0))} -> 1502 | J34: PROPIOS | K34: 1500
C35: PROMINENT FLUID CONTROLS DE MEXICO | D35: MANIOBRAS AA | E35: 5826.96 | F35: 0 | G35: JMA6000225 | H35: CDMX | I35: {=INDEX(CC!C:C,MATCH(1,(CC!A:A=H35)*(CC!B:B=J35),0))} -> 1503 | J35: TERCEROS | K35: 5826.96
C36: PROMINENT FLUID CONTROLS DE MEXICO | D36: CONTRAPRESTACIÓN | E36: 36.29 | F36: 0 | G36: JMA6000225 | H36: CDMX | I36: {=INDEX(CC!C:C,MATCH(1,(CC!A:A=H36)*(CC!B:B=J36),0))} -> 1502 | J36: PROPIOS | K36: 36.29
C37: PROMINENT FLUID CONTROLS DE MEXICO | D37: ASESORIA ADUANAL | E37: 827.44 | F37: 0 | G37: JMA6000225 | H37: CDMX | I37: {=INDEX(CC!C:C,MATCH(1,(CC!A:A=H37)*(CC!B:B=J37),0))} -> 1502 | J37: PROPIOS | K37: 827.44
B38: MXN | C38: CARGA AEREA CONSOLIDADA | D38: TRANSPORTE | E38: 0.01 | F38: 0 | G38: DHL03082026 | H38: DHL | I38: {=INDEX(CC!C:C,MATCH(1,(CC!A:A=H38)*(CC!B:B=J38),0))} -> 502 | J38: PROPIOS | K38: 0.01
B39: MXN | C39: PROMINENT FLUID CONTROLS DE MEXICO | D39: TRANSPORTE | E39: 4150 | F39: 0 | G39: JMA6000225 | H39: TRANSITO | I39: {=INDEX(CC!C:C,MATCH(1,(CC!A:A=H39)*(CC!B:B=J39),0))} -> 602 | J39: PROPIOS | K39: 4150
B40: MXN | C40: CREATIVA TCH | D40: TRANSPORTE | E40: 8050 | F40: 0 | G40: JML6000215 | H40: LAREDO | I40: {=INDEX(CC!C:C,MATCH(1,(CC!A:A=H40)*(CC!B:B=J40),0))} -> 1302 | J40: PROPIOS | K40: 8050
...

Sheet reglas
A1: ID | B1: EMISOR | C1: PATRÓN | D1: CONCEPTO | E1: TIPO DE BÚSQUEDA
A2: 1 | B2: CUALQUIERA | C2: TARIFA | D2: TRANSPORTES LOCALES | E2: EXACTA
A3: 2 | B3: CUALQUIERA | C3: TARIFA DE CANCELACION | D3: TRANSPORTES LOCALES | E3: EXACTA
A4: 3 | B4: AAACESA, ALMACENES FISCALIZADOS, S.A. DE C.V. | C4: MANEJO POR VALOR | D4: MANIOBRAS | E4: CONTIENE
A5: 4 | B5: AAACESA, ALMACENES FISCALIZADOS, S.A. DE C.V. | C5: ALMACENAJE | D5: MANIOBRAS | E5: CONTIENE
A6: 5 | B6: AAACESA, ALMACENES FISCALIZADOS, S.A. DE C.V. | C6: MANTRANSFER | D6: MANIOBRAS | E6: CONTIENE
A7: 6 | B7: AAACESA, ALMACENES FISCALIZADOS, S.A. DE C.V. | C7: COSTO DE TRANSFERENCIA | D7: MANIOBRAS | E7: CONTIENE
A8: 7 | B8: AAACESA, ALMACENES FISCALIZADOS, S.A. DE C.V. | C8: MANIOBRAS PARA EL RECONOCIMIENTO PREVIO | D8: MANIOBRAS | E8: CONTIENE
A9: 8 | B9: SUALSA | C9: PALETIZADA TOTAL DE TRAILER | D9: MANIOBRAS | E9: CONTIENE
A10: 9 | B10: DHL GLOBAL FORWARDING (MEXICO) | C10: SEPARACION DE EMBARQUES EN DESTINO | D10: MANIOBRAS | E10: CONTIENE
A11: 10 | B11: DHL GLOBAL FORWARDING (MEXICO) | C11: MANEJO EN TERMINAL FORWARDER EN DESTINO | D11: MANIOBRAS | E11: CONTIENE
A12: 11 | B12: DHL EXPRESS MEXICO | C12: * | D12: GUIAS | E12: SOLO EMISOR
A13: 12 | B13: E-LEVEL CLOUD SERVICES | C13: MICROSOFT 365 BUSINESS PREMIUM | D13: LICENCIAS 365 | E13: CONTIENE
... A235: 234 | B235: MARGARITA TERESA LOERA VAZQUEZ | C235: Etiquetas Adhesivas | D235: ETIQUETADO AA | E235: CONTIENE

Sheet CC
A1: cc | B1: tipo | C1: cc
A2: staff | B2: PROPIOS | C2: 102
A3: Amazon 1 | B3: PROPIOS | C3: 202
A4: Amazon 2 | B4: PROPIOS | C4: 302
A5: estafeta | B5: PROPIOS | C5: 402
A6: estafeta | B6: TERCEROS | C6: 403
A7: dhl | B7: PROPIOS | C7: 502
A8: dhl | B8: TERCEROS | C8: 503
A9: Transito | B9: PROPIOS | C9: 602
A10: Transito | B10: TERCEROS | C10: 603
A11: Tijuana | B11: PROPIOS | C11: 702
A12: Tijuana | B12: TERCEROS | C12: 703
A13: Mexicali | B13: PROPIOS | C13: 802
... A35: TMM | B35: TERCEROS | C35: 2003

Sheet recibidas
A1: TipoCambio | B1: Moneda | C1: EmisorNombre | D1: Descripcion | E1: Importe | F1: DescuentoConcepto | G1: ADUANA | H1: CC | I1: TIPO | J1: monto 1 | K1: CONCEPTO PARA CIERRE
A2: 1 | B2: MXN | C2: CONFEDERACION LATINOAMERICANA DE AGENTES ADUANALES | D2: CUOTA MENSUAL | E2: 13480 | F2: 0 | G2: VERACRUZ | H2: {=INDEX(CC!C:C,MATCH(1,(CC!A:A=G2)*(CC!B:B=I2),0))} -> 1702 | I2: PROPIOS | J2: 13480 | K2: =IFERROR(__xludf.DUMMYFUNCTION("IFERROR( INDEX( FILTER( MAP( reglas!$B$2:$B$240, reglas!$C$2:$C$240, reglas!$D$2:$D$240, reglas!$E$2:$E$240, LAMBDA(rEmisor,rPatron,rConcepto,rTipo, IF( AND( OR( UPPER(TRIM(rEmisor))=UPPER(TRIM(C2)), UPPER(TRIM(rEmisor))=""CUALQUIERA"" ), OR( UPPER(TRIM(r"&"Tipo))=""SOLO EMISOR"", AND( UPPER(TRIM(rTipo))=""EXACTA"", UPPER(TRIM(AG2))=UPPER(TRIM(rPatron)) ), AND( OR( UPPER(TRIM(rTipo))=""CONTIENE"", UPPER(TRIM(rTipo))=""COINCIDENCIA"" ), ISNUMBER(SEARCH(UPPER(TRIM(rPatron)),UPPER(TRIM(D2)))) ) ) ), rConcepto, "&""""" ) ) ), MAP( reglas!$B$2:$B$240, reglas!$C$2:$C$240, reglas!$D$2:$D$240, reglas!$E$2:$E$240, LAMBDA(rEmisor,rPatron,rConcepto,rTipo, IF( AND( OR( UPPER(TRIM(rEmisor))=UPPER(TRIM(C2)), UPPER(TRIM(rEmisor))=""CUALQUIERA"" ), OR( UPPER(TRIM(rTipo))=""SOL"&"O EMISOR"", AND( UPPER(TRIM(rTipo))=""EXACTA"", UPPER(TRIM(D2))=UPPER(TRIM(rPatron)) ), AND( OR( UPPER(TRIM(rTipo))=""CONTIENE"", UPPER(TRIM(rTipo))=""COINCIDENCIA"" ), ISNUMBER(SEARCH(UPPER(TRIM(rPatron)),UPPER(TRIM(D2)))) ) ) ), rConcepto, """" ) ) )<>"&""""" ), 1 ), """" )"),"CUOTAS Y SUSCRIPCIONES") -> CUOTAS Y SUSCRIPCIONES
C3: CONFEDERACION LATINOAMERICANA DE AGENTES ADUANALES | D3: CUOTA POR ADUANA, COBRO ADICIONAL POR ADUANA CON SEDES DE CLAA (VERACRUZ,AIFA,MANZANILLO) | E3: 3423 | F3: 0 | G3: VERACRUZ | H3: {=INDEX(CC!C:C,MATCH(1,(CC!A:A=G3)*(CC!B:B=I3),0))} -> 1702 | I3: PROPIOS | J3: 1141 | K3: =IFERROR(__xludf.DUMMYFUNCTION("IFERROR( INDEX( FILTER( MAP( reglas!$B$2:$B$240, reglas!$C$2:$C$240, reglas!$D$2:$D$240, reglas!$E$2:$E$240, LAMBDA(rEmisor,rPatron,rConcepto,rTipo, IF( AND( OR( UPPER(TRIM(rEmisor))=UPPER(TRIM(C3)), UPPER(TRIM(rEmisor))=""CUALQUIERA"" ), OR( UPPER(TRIM(r"&"Tipo))=""SOLO EMISOR"", AND( UPPER(TRIM(rTipo))=""EXACTA"", UPPER(TRIM(AG3))=UPPER(TRIM(rPatron)) ), AND( OR( UPPER(TRIM(rTipo))=""CONTIENE"", UPPER(TRIM(rTipo))=""COINCIDENCIA"" ), ISNUMBER(SEARCH(UPPER(TRIM(rPatron)),UPPER(TRIM(D3)))) ) ) ), rConcepto, "&""""" ) ) ), MAP( reglas!$B$2:$B$240, reglas!$C$2:$C$240, reglas!$D$2:$D$240, reglas!$E$2:$E$240, LAMBDA(rEmisor,rPatron,rConcepto,rTipo, IF( AND( OR( UPPER(TRIM(rEmisor))=UPPER(TRIM(C3)), UPPER(TRIM(rEmisor))=""CUALQUIERA"" ), OR( UPPER(TRIM(rTipo))=""SOL"&"O EMISOR"", AND( UPPER(TRIM(rTipo))=""EXACTA"", UPPER(TRIM(D3))=UPPER(TRIM(rPatron)) ), AND( OR( UPPER(TRIM(rTipo))=""CONTIENE"", UPPER(TRIM(rTipo))=""COINCIDENCIA"" ), ISNUMBER(SEARCH(UPPER(TRIM(rPatron)),UPPER(TRIM(D3)))) ) ) ), rConcepto, """" ) ) )<>"&""""" ), 1 ), """" )"),"CUOTAS Y SUSCRIPCIONES") -> CUOTAS Y SUSCRIPCIONES
C4: CONFEDERACION LATINOAMERICANA DE AGENTES ADUANALES | D4: CUOTA POR ADUANA, COBRO ADICIONAL POR ADUANA CON SEDES DE CLAA (VERACRUZ,AIFA,MANZANILLO) | G4: AIFA | H4: {=INDEX(CC!C:C,MATCH(1,(CC!A:A=G4)*(CC!B:B=I4),0))} -> 902 | I4: PROPIOS | J4: 1141 | K4: =IFERROR(__xludf.DUMMYFUNCTION("IFERROR( INDEX( FILTER( MAP( reglas!$B$2:$B$240, reglas!$C$2:$C$240, reglas!$D$2:$D$240, reglas!$E$2:$E$240, LAMBDA(rEmisor,rPatron,rConcepto,rTipo, IF( AND( OR( UPPER(TRIM(rEmisor))=UPPER(TRIM(C4)), UPPER(TRIM(rEmisor))=""CUALQUIERA"" ), OR( UPPER(TRIM(r"&"Tipo))=""SOLO EMISOR"", AND( UPPER(TRIM(rTipo))=""EXACTA"", UPPER(TRIM(AG4))=UPPER(TRIM(rPatron)) ), AND( OR( UPPER(TRIM(rTipo))=""CONTIENE"", UPPER(TRIM(rTipo))=""COINCIDENCIA"" ), ISNUMBER(SEARCH(UPPER(TRIM(rPatron)),UPPER(TRIM(D4)))) ) ) ), rConcepto, "&""""" ) ) ), MAP( reglas!$B$2:$B$240, reglas!$C$2:$C$240, reglas!$D$2:$D$240, reglas!$E$2:$E$240, LAMBDA(rEmisor,rPatron,rConcepto,rTipo, IF( AND( OR( UPPER(TRIM(rEmisor))=UPPER(TRIM(C4)), UPPER(TRIM(rEmisor))=""CUALQUIERA"" ), OR( UPPER(TRIM(rTipo))=""SOL"&"O EMISOR"", AND( UPPER(TRIM(rTipo))=""EXACTA"", UPPER(TRIM(D4))=UPPER(TRIM(rPatron)) ), AND( OR( UPPER(TRIM(rTipo))=""CONTIENE"", UPPER(TRIM(rTipo))=""COINCIDENCIA"" ), ISNUMBER(SEARCH(UPPER(TRIM(rPatron)),UPPER(TRIM(D4)))) ) ) ), rConcepto, """" ) ) )<>"&""""" ), 1 ), """" )"),"CUOTAS Y SUSCRIPCIONES") -> CUOTAS Y SUSCRIPCIONES
C5: CONFEDERACION LATINOAMERICANA DE AGENTES ADUANALES | D5: CUOTA POR ADUANA, COBRO ADICIONAL POR ADUANA CON SEDES DE CLAA (VERACRUZ,AIFA,MANZANILLO) | G5: MANZANILLO | H5: {=INDEX(CC!C:C,MATCH(1,(CC!A:A=G5)*(CC!B:B=I5),0))} -> 1202 | I5: PROPIOS | J5: 1141 | K5: =IFERROR(__xludf.DUMMYFUNCTION("IFERROR( INDEX( FILTER( MAP( reglas!$B$2:$B$240, reglas!$C$2:$C$240, reglas!$D$2:$D$240, reglas!$E$2:$E$240, LAMBDA(rEmisor,rPatron,rConcepto,rTipo, IF( AND( OR( UPPER(TRIM(rEmisor))=UPPER(TRIM(C5)), UPPER(TRIM(rEmisor))=""CUALQUIERA"" ), OR( UPPER(TRIM(r"&"Tipo))=""SOLO EMISOR"", AND( UPPER(TRIM(rTipo))=""EXACTA"", UPPER(TRIM(AG5))=UPPER(TRIM(rPatron)) ), AND( OR( UPPER(TRIM(rTipo))=""CONTIENE"", UPPER(TRIM(rTipo))=""COINCIDENCIA"" ), ISNUMBER(SEARCH(UPPER(TRIM(rPatron)),UPPER(TRIM(D5)))) ) ) ), rConcepto, "&""""" ) ) ), MAP( reglas!$B$2:$B$240, reglas!$C$2:$C$240, reglas!$D$2:$D$240, reglas!$E$2:$E$240, LAMBDA(rEmisor,rPatron,rConcepto,rTipo, IF( AND( OR( UPPER(TRIM(rEmisor))=UPPER(TRIM(C5)), UPPER(TRIM(rEmisor))=""CUALQUIERA"" ), OR( UPPER(TRIM(rTipo))=""SOL"&"O EMISOR"", AND( UPPER(TRIM(rTipo))=""EXACTA"", UPPER(TRIM(D5))=UPPER(TRIM(rPatron)) ), AND( OR( UPPER(TRIM(rTipo))=""CONTIENE"", UPPER(TRIM(rTipo))=""COINCIDENCIA"" ), ISNUMBER(SEARCH(UPPER(TRIM(rPatron)),UPPER(TRIM(D5)))) ) ) ), rConcepto, """" ) ) )<>"&""""" ), 1 ), """" )"),"CUOTAS Y SUSCRIPCIONES") -> CUOTAS Y SUSCRIPCIONES
B6: MXN | C6: CRISTOFER PAZ JIMENEZ | D6: FLETE LOCAL ADUANA AIFA A CUAUTITLÁN, EDO. MÉX. 04/08/2026. | E6: 11500 | F6: 0 | G6: IMILE AIFA | H6: {=INDEX(CC!C:C,MATCH(1,(CC!A:A=G6)*(CC!B:B=I6),0))} -> 1402 | I6: PROPIOS | J6: 11500 | K6: =IFERROR(__xludf.DUMMYFUNCTION("IFERROR( INDEX( FILTER( MAP( reglas!$B$2:$B$240, reglas!$C$2:$C$240, reglas!$D$2:$D$240, reglas!$E$2:$E$240, LAMBDA(rEmisor,rPatron,rConcepto,rTipo, IF( AND( OR( UPPER(TRIM(rEmisor))=UPPER(TRIM(C6)), UPPER(TRIM(rEmisor))=""CUALQUIERA"" ), OR( UPPER(TRIM(r"&"Tipo))=""SOLO EMISOR"", AND( UPPER(TRIM(rTipo))=""EXACTA"", UPPER(TRIM(AG6))=UPPER(TRIM(rPatron)) ), AND( OR( UPPER(TRIM(rTipo))=""CONTIENE"", UPPER(TRIM(rTipo))=""COINCIDENCIA"" ), ISNUMBER(SEARCH(UPPER(TRIM(rPatron)),UPPER(TRIM(D6)))) ) ) ), rConcepto, "&""""" ) ) ), MAP( reglas!$B$2:$B$240, reglas!$C$2:$C$240, reglas!$D$2:$D$240, reglas!$E$2:$E$240, LAMBDA(rEmisor,rPatron,rConcepto,rTipo, IF( AND( OR( UPPER(TRIM(rEmisor))=UPPER(TRIM(C6)), UPPER(TRIM(rEmisor))=""CUALQUIERA"" ), OR( UPPER(TRIM(rTipo))=""SOL"&"O EMISOR"", AND( UPPER(TRIM(rTipo))=""EXACTA"", UPPER(TRIM(D6))=UPPER(TRIM(rPatron)) ), AND( OR( UPPER(TRIM(rTipo))=""CONTIENE"", UPPER(TRIM(rTipo))=""COINCIDENCIA"" ), ISNUMBER(SEARCH(UPPER(TRIM(rPatron)),UPPER(TRIM(D6)))) ) ) ), rConcepto, """" ) ) )<>"&""""" ), 1 ), """" )"),"TRANSPORTE") -> TRANSPORTE
B7: MXN | C7: SISTEMA UNIFICADO DE MANIOBRAS AEREAS PARA AGENTES ADUANALES | D7: Carga de camión | E7: 3500 | F7: 0 | G7: IMILE AIFA | H7: {=INDEX(CC!C:C,MATCH(1,(CC!A:A=G7)*(CC!B:B=I7),0))} -> 1402 | I7: PROPIOS | J7: 3500 | K7: =IFERROR(__xludf.DUMMYFUNCTION("IFERROR( INDEX( FILTER( MAP( reglas!$B$2:$B$240, reglas!$C$2:$C$240, reglas!$D$2:$D$240, reglas!$E$2:$E$240, LAMBDA(rEmisor,rPatron,rConcepto,rTipo, IF( AND( OR( UPPER(TRIM(rEmisor))=UPPER(TRIM(C7)), UPPER(TRIM(rEmisor))=""CUALQUIERA"" ), OR( UPPER(TRIM(r"&"Tipo))=""SOLO EMISOR"", AND( UPPER(TRIM(rTipo))=""EXACTA"", UPPER(TRIM(AG7))=UPPER(TRIM(rPatron)) ), AND( OR( UPPER(TRIM(rTipo))=""CONTIENE"", UPPER(TRIM(rTipo))=""COINCIDENCIA"" ), ISNUMBER(SEARCH(UPPER(TRIM(rPatron)),UPPER(TRIM(D7)))) ) ) ), rConcepto, "&""""" ) ) ), MAP( reglas!$B$2:$B$240, reglas!$C$2:$C$240, reglas!$D$2:$D$240, reglas!$E$2:$E$240, LAMBDA(rEmisor,rPatron,rConcepto,rTipo, IF( AND( OR( UPPER(TRIM(rEmisor))=UPPER(TRIM(C7)), UPPER(TRIM(rEmisor))=""CUALQUIERA"" ), OR( UPPER(TRIM(rTipo))=""SOL"&"O EMISOR"", AND( UPPER(TRIM(rTipo))=""EXACTA"", UPPER(TRIM(D7))=UPPER(TRIM(rPatron)) ), AND( OR( UPPER(TRIM(rTipo))=""CONTIENE"", UPPER(TRIM(rTipo))=""COINCIDENCIA"" ), ISNUMBER(SEARCH(UPPER(TRIM(rPatron)),UPPER(TRIM(D7)))) ) ) ), rConcepto, """" ) ) )<>"&""""" ), 1 ), """" )"),"MANIOBRAS") -> MANIOBRAS
B8: MXN | C8: CRISTOFER PAZ JIMENEZ | D8: FLETE LOCAL ADUANA AIFA A CUAUTITLÁN, EDO. MÉX. 03/08/2026. | E8: 11500 | F8: 0 | G8: IMILE AIFA | H8: {=INDEX(CC!C:C,MATCH(1,(CC!A:A=G8)*(CC!B:B=I8),0))} -> 1402 | I8: PROPIOS | J8: 11500 | K8: =IFERROR(__xludf.DUMMYFUNCTION("IFERROR( INDEX( FILTER( MAP( reglas!$B$2:$B$240, reglas!$C$2:$C$240, reglas!$D$2:$D$240, reglas!$E$2:$E$240, LAMBDA(rEmisor,rPatron,rConcepto,rTipo, IF( AND( OR( UPPER(TRIM(rEmisor))=UPPER(TRIM(C8)), UPPER(TRIM(rEmisor))=""CUALQUIERA"" ), OR( UPPER(TRIM(r"&"Tipo))=""SOLO EMISOR"", AND( UPPER(TRIM(rTipo))=""EXACTA"", UPPER(TRIM(AG8))=UPPER(TRIM(rPatron)) ), AND( OR( UPPER(TRIM(rTipo))=""CONTIENE"", UPPER(TRIM(rTipo))=""COINCIDENCIA"" ), ISNUMBER(SEARCH(UPPER(TRIM(rPatron)),UPPER(TRIM(D8)))) ) ) ), rConcepto, "&""""" ) ) ), MAP( reglas!$B$2:$B$240, reglas!$C$2:$C$240, reglas!$D$2:$D$240, reglas!$E$2:$E$240, LAMBDA(rEmisor,rPatron,rConcepto,rTipo, IF( AND( OR( UPPER(TRIM(rEmisor))=UPPER(TRIM(C8)), UPPER(TRIM(rEmisor))=""CUALQUIERA"" ), OR( UPPER(TRIM(rTipo))=""SOL"&"O EMISOR"", AND( UPPER(TRIM(rTipo))=""EXACTA"", UPPER(TRIM(D8))=UPPER(TRIM(rPatron)) ), AND( OR( UPPER(TRIM(rTipo))=""CONTIENE"", UPPER(TRIM(rTipo))=""COINCIDENCIA"" ), ISNUMBER(SEARCH(UPPER(TRIM(rPatron)),UPPER(TRIM(D8)))) ) ) ), rConcepto, """" ) ) )<>"&""""" ), 1 ), """" )"),"TRANSPORTE") -> TRANSPORTE
B9: MXN | C9: CRISTOFER PAZ JIMENEZ | D9: FLETE LOCAL ADUANA AIFA A CUAUTITLÁN, EDO. MÉX. 01/08/2026. | E9: 11500 | F9: 0 | G9: IMILE AIFA | H9: {=INDEX(CC!C:C,MATCH(1,(CC!A:A=G9)*(CC!B:B=I9),0))} -> 1402 | I9: PROPIOS | J9: 11500 | K9: =IFERROR(__xludf.DUMMYFUNCTION("IFERROR( INDEX( FILTER( MAP( reglas!$B$2:$B$240, reglas!$C$2:$C$240, reglas!$D$2:$D$240, reglas!$E$2:$E$240, LAMBDA(rEmisor,rPatron,rConcepto,rTipo, IF( AND( OR( UPPER(TRIM(rEmisor))=UPPER(TRIM(C9)), UPPER(TRIM(rEmisor))=""CUALQUIERA"" ), OR( UPPER(TRIM(r"&"Tipo))=""SOLO EMISOR"", AND( UPPER(TRIM(rTipo))=""EXACTA"", UPPER(TRIM(AG9))=UPPER(TRIM(rPatron)) ), AND( OR( UPPER(TRIM(rTipo))=""CONTIENE"", UPPER(TRIM(rTipo))=""COINCIDENCIA"" ), ISNUMBER(SEARCH(UPPER(TRIM(rPatron)),UPPER(TRIM(D9)))) ) ) ), rConcepto, "&""""" ) ) ), MAP( reglas!$B$2:$B$240, reglas!$C$2:$C$240, reglas!$D$2:$D$240, reglas!$E$2:$E$240, LAMBDA(rEmisor,rPatron,rConcepto,rTipo, IF( AND( OR( UPPER(TRIM(rEmisor))=UPPER(TRIM(C9)), UPPER(TRIM(rEmisor))=""CUALQUIERA"" ), OR( UPPER(TRIM(rTipo))=""SOL"&"O EMISOR"", AND( UPPER(TRIM(rTipo))=""EXACTA"", UPPER(TRIM(D9))=UPPER(TRIM(rPatron)) ), AND( OR( UPPER(TRIM(rTipo))=""CONTIENE"", UPPER(TRIM(rTipo))=""COINCIDENCIA"" ), ISNUMBER(SEARCH(UPPER(TRIM(rPatron)),UPPER(TRIM(D9)))) ) ) ), rConcepto, """" ) ) )<>"&""""" ), 1 ), """" )"),"TRANSPORTE") -> TRANSPORTE
A10: 1 | B10: MXN | C10: GOOGLE CLOUD MEXICO | D10: Servicios de workspace | E10: 140 | F10: 0 | G10: STAFF | H10: {=INDEX(CC!C:C,MATCH(1,(CC!A:A=G10)*(CC!B:B=I10),0))} -> 102 | I10: PROPIOS | J10: 140 | K10: =IFERROR(__xludf.DUMMYFUNCTION("IFERROR( INDEX( FILTER( MAP( reglas!$B$2:$B$240, reglas!$C$2:$C$240, reglas!$D$2:$D$240, reglas!$E$2:$E$240, LAMBDA(rEmisor,rPatron,rConcepto,rTipo, IF( AND( OR( UPPER(TRIM(rEmisor))=UPPER(TRIM(C10)), UPPER(TRIM(rEmisor))=""CUALQUIERA"" ), OR( UPPER(TRIM("&"rTipo))=""SOLO EMISOR"", AND( UPPER(TRIM(rTipo))=""EXACTA"", UPPER(TRIM(AG10))=UPPER(TRIM(rPatron)) ), AND( OR( UPPER(TRIM(rTipo))=""CONTIENE"", UPPER(TRIM(rTipo))=""COINCIDENCIA"" ), ISNUMBER(SEARCH(UPPER(TRIM(rPatron)),UPPER(TRIM(D10)))) ) ) ), rConcept"&"o, """" ) ) ), MAP( reglas!$B$2:$B$240, reglas!$C$2:$C$240, reglas!$D$2:$D$240, reglas!$E$2:$E$240, LAMBDA(rEmisor,rPatron,rConcepto,rTipo, IF( AND( OR( UPPER(TRIM(rEmisor))=UPPER(TRIM(C10)), UPPER(TRIM(rEmisor))=""CUALQUIERA"" ), OR( UPPER(TRIM(rTipo))="&"""SOLO EMISOR"", AND( UPPER(TRIM(rTipo))=""EXACTA"", UPPER(TRIM(D10))=UPPER(TRIM(rPatron)) ), AND( OR( UPPER(TRIM(rTipo))=""CONTIENE"", UPPER(TRIM(rTipo))=""COINCIDENCIA"" ), ISNUMBER(SEARCH(UPPER(TRIM(rPatron)),UPPER(TRIM(D10)))) ) ) ), rConcepto, """" )"&" ) )<>"""" ), 1 ), """" )"),"SERVICIO EN LA NUBE") -> SERVICIO EN LA NUBE
B11: MXN | C11: MEGACABLE COMUNICACIONES DE MEXICO | D11: Internet MetroC Facturación del 01 de Agosto al 31 de Agosto de 2026 1060760956 | E11: 6800 | F11: 0 | G11: TOLUCA | H11: {=INDEX(CC!C:C,MATCH(1,(CC!A:A=G11)*(CC!B:B=I11),0))} -> 1002 | I11: PROPIOS | J11: 6800 | K11: =IFERROR(__xludf.DUMMYFUNCTION("IFERROR( INDEX( FILTER( MAP( reglas!$B$2:$B$240, reglas!$C$2:$C$240, reglas!$D$2:$D$240, reglas!$E$2:$E$240, LAMBDA(rEmisor,rPatron,rConcepto,rTipo, IF( AND( OR( UPPER(TRIM(rEmisor))=UPPER(TRIM(C11)), UPPER(TRIM(rEmisor))=""CUALQUIERA"" ), OR( UPPER(TRIM("&"rTipo))=""SOLO EMISOR"", AND( UPPER(TRIM(rTipo))=""EXACTA"", UPPER(TRIM(AG11))=UPPER(TRIM(rPatron)) ), AND( OR( UPPER(TRIM(rTipo))=""CONTIENE"", UPPER(TRIM(rTipo))=""COINCIDENCIA"" ), ISNUMBER(SEARCH(UPPER(TRIM(rPatron)),UPPER(TRIM(D11)))) ) ) ), rConcept"&"o, """" ) ) ), MAP( reglas!$B$2:$B$240, reglas!$C$2:$C$240, reglas!$D$2:$D$240, reglas!$E$2:$E$240, LAMBDA(rEmisor,rPatron,rConcepto,rTipo, IF( AND( OR( UPPER(TRIM(rEmisor))=UPPER(TRIM(C11)), UPPER(TRIM(rEmisor))=""CUALQUIERA"" ), OR( UPPER(TRIM(rTipo))="&"""SOLO EMISOR"", AND( UPPER(TRIM(rTipo))=""EXACTA"", UPPER(TRIM(D11))=UPPER(TRIM(rPatron)) ), AND( OR( UPPER(TRIM(rTipo))=""CONTIENE"", UPPER(TRIM(rTipo))=""COINCIDENCIA"" ), ISNUMBER(SEARCH(UPPER(TRIM(rPatron)),UPPER(TRIM(D11)))) ) ) ), rConcepto, """" )"&" ) )<>"""" ), 1 ), """" )"),"INTERNET") -> INTERNET
B12: MXN | C12: CRISTOFER PAZ JIMENEZ | D12: FLETE LOCAL ADUANA AIFA A CUAUTITLÁN, EDO. MÉX. 03/08/2026. | E12: 11500 | F12: 0 | G12: IMILE AIFA | H12: {=INDEX(CC!C:C,MATCH(1,(CC!A:A=G12)*(CC!B:B=I12),0))} -> 1402 | I12: PROPIOS | J12: 11500 | K12: =IFERROR(__xludf.DUMMYFUNCTION("IFERROR( INDEX( FILTER( MAP( reglas!$B$2:$B$240, reglas!$C$2:$C$240, reglas!$D$2:$D$240, reglas!$E$2:$E$240, LAMBDA(rEmisor,rPatron,rConcepto,rTipo, IF( AND( OR( UPPER(TRIM(rEmisor))=UPPER(TRIM(C12)), UPPER(TRIM(rEmisor))=""CUALQUIERA"" ), OR( UPPER(TRIM("&"rTipo))=""SOLO EMISOR"", AND( UPPER(TRIM(rTipo))=""EXACTA"", UPPER(TRIM(AG12))=UPPER(TRIM(rPatron)) ), AND( OR( UPPER(TRIM(rTipo))=""CONTIENE"", UPPER(TRIM(rTipo))=""COINCIDENCIA"" ), ISNUMBER(SEARCH(UPPER(TRIM(rPatron)),UPPER(TRIM(D12)))) ) ) ), rConcept"&"o, """" ) ) ), MAP( reglas!$B$2:$B$240, reglas!$C$2:$C$240, reglas!$D$2:$D$240, reglas!$E$2:$E$240, LAMBDA(rEmisor,rPatron,rConcepto,rTipo, IF( AND( OR( UPPER(TRIM(rEmisor))=UPPER(TRIM(C12)), UPPER(TRIM(rEmisor))=""CUALQUIERA"" ), OR( UPPER(TRIM(rTipo))="&"""SOLO EMISOR"", AND( UPPER(TRIM(rTipo))=""EXACTA"", UPPER(TRIM(D12))=UPPER(TRIM(rPatron)) ), AND( OR( UPPER(TRIM(rTipo))=""CONTIENE"", UPPER(TRIM(rTipo))=""COINCIDENCIA"" ), ISNUMBER(SEARCH(UPPER(TRIM(rPatron)),UPPER(TRIM(D12)))) ) ) ), rConcepto, """" )"&" ) )<>"""" ), 1 ), """" )"),"TRANSPORTE") -> TRANSPORTE
B13: MXN | C13: CRISTOFER PAZ JIMENEZ | D13: FLETE LOCAL ADUANA AIFA A CUAUTITLÁN, EDO. MÉX. 01/08/2026. | E13: 11500 | F13: 0 | G13: IMILE AIFA | H13: {=INDEX(CC!C:C,MATCH(1,(CC!A:A=G13)*(CC!B:B=I13),0))} -> 1402 | I13: PROPIOS | J13: 11500 | K13: =IFERROR(__xludf.DUMMYFUNCTION("IFERROR( INDEX( FILTER( MAP( reglas!$B$2:$B$240, reglas!$C$2:$C$240, reglas!$D$2:$D$240, reglas!$E$2:$E$240, LAMBDA(rEmisor,rPatron,rConcepto,rTipo, IF( AND( OR( UPPER(TRIM(rEmisor))=UPPER(TRIM(C13)), UPPER(TRIM(rEmisor))=""CUALQUIERA"" ), OR( UPPER(TRIM("&"rTipo))=""SOLO EMISOR"", AND( UPPER(TRIM(rTipo))=""EXACTA"", UPPER(TRIM(AG13))=UPPER(TRIM(rPatron)) ), AND( OR( UPPER(TRIM(rTipo))=""CONTIENE"", UPPER(TRIM(rTipo))=""COINCIDENCIA"" ), ISNUMBER(SEARCH(UPPER(TRIM(rPatron)),UPPER(TRIM(D13)))) ) ) ), rConcept"&"o, """" ) ) ), MAP( reglas!$B$2:$B$240, reglas!$C$2:$C$240, reglas!$D$2:$D$240, reglas!$E$2:$E$240, LAMBDA(rEmisor,rPatron,rConcepto,rTipo, IF( AND( OR( UPPER(TRIM(rEmisor))=UPPER(TRIM(C13)), UPPER(TRIM(rEmisor))=""CUALQUIERA"" ), OR( UPPER(TRIM(rTipo))="&"""SOLO EMISOR"", AND( UPPER(TRIM(rTipo))=""EXACTA"", UPPER(TRIM(D13))=UPPER(TRIM(rPatron)) ), AND( OR( UPPER(TRIM(rTipo))=""CONTIENE"", UPPER(TRIM(rTipo))=""COINCIDENCIA"" ), ISNUMBER(SEARCH(UPPER(TRIM(rPatron)),UPPER(TRIM(D13)))) ) ) ), rConcepto, """" )"&" ) )<>"""" ), 1 ), """" )"),"TRANSPORTE") -> TRANSPORTE
B14: MXN | C14: SISTEMA UNIFICADO DE MANIOBRAS AEREAS PARA AGENTES ADUANALES | D14: Carga de camión | E14: 3500 | F14: 0 | G14: IMILE AIFA | H14: {=INDEX(CC!C:C,MATCH(1,(CC!A:A=G14)*(CC!B:B=I14),0))} -> 1402 | I14: PROPIOS | J14: 3500 | K14: =IFERROR(__xludf.DUMMYFUNCTION("IFERROR( INDEX( FILTER( MAP( reglas!$B$2:$B$240, reglas!$C$2:$C$240, reglas!$D$2:$D$240, reglas!$E$2:$E$240, LAMBDA(rEmisor,rPatron,rConcepto,rTipo, IF( AND( OR( UPPER(TRIM(rEmisor))=UPPER(TRIM(C14)), UPPER(TRIM(rEmisor))=""CUALQUIERA"" ), OR( UPPER(TRIM("&"rTipo))=""SOLO EMISOR"", AND( UPPER(TRIM(rTipo))=""EXACTA"", UPPER(TRIM(AG14))=UPPER(TRIM(rPatron)) ), AND( OR( UPPER(TRIM(rTipo))=""CONTIENE"", UPPER(TRIM(rTipo))=""COINCIDENCIA"" ), ISNUMBER(SEARCH(UPPER(TRIM(rPatron)),UPPER(TRIM(D14)))) ) ) ), rConcept"&"o, """" ) ) ), MAP( reglas!$B$2:$B$240, reglas!$C$2:$C$240, reglas!$D$2:$D$240, reglas!$E$2:$E$240, LAMBDA(rEmisor,rPatron,rConcepto,rTipo, IF( AND( OR( UPPER(TRIM(rEmisor))=UPPER(TRIM(C14)), UPPER(TRIM(rEmisor))=""CUALQUIERA"" ), OR( UPPER(TRIM(rTipo))="&"""SOLO EMISOR"", AND( UPPER(TRIM(rTipo))=""EXACTA"", UPPER(TRIM(D14))=UPPER(TRIM(rPatron)) ), AND( OR( UPPER(TRIM(rTipo))=""CONTIENE"", UPPER(TRIM(rTipo))=""COINCIDENCIA"" ), ISNUMBER(SEARCH(UPPER(TRIM(rPatron)),UPPER(TRIM(D14)))) ) ) ), rConcepto, """" )"&" ) )<>"""" ), 1 ), """" )"),"MANIOBRAS") -> MANIOBRAS
B15: MXN | C15: JORGE ANGEL GOMEZ TERRAZAS | D15: Consultoria Gestión y Estrategia en Negocios | E15: 212500 | F15: 0 | G15: STAFF | H15: {=INDEX(CC!C:C,MATCH(1,(CC!A:A=G15)*(CC!B:B=I15),0))} -> 102 | I15: PROPIOS | K15: =IFERROR(__xludf.DUMMYFUNCTION("IFERROR( INDEX( FILTER( MAP( reglas!$B$2:$B$240, reglas!$C$2:$C$240, reglas!$D$2:$D$240, reglas!$E$2:$E$240, LAMBDA(rEmisor,rPatron,rConcepto,rTipo, IF( AND( OR( UPPER(TRIM(rEmisor))=UPPER(TRIM(C15)), UPPER(TRIM(rEmisor))=""CUALQUIERA"" ), OR( UPPER(TRIM("&"rTipo))=""SOLO EMISOR"", AND( UPPER(TRIM(rTipo))=""EXACTA"", UPPER(TRIM(AG15))=UPPER(TRIM(rPatron)) ), AND( OR( UPPER(TRIM(rTipo))=""CONTIENE"", UPPER(TRIM(rTipo))=""COINCIDENCIA"" ), ISNUMBER(SEARCH(UPPER(TRIM(rPatron)),UPPER(TRIM(D15)))) ) ) ), rConcept"&"o, """" ) ) ), MAP( reglas!$B$2:$B$240, reglas!$C$2:$C$240, reglas!$D$2:$D$240, reglas!$E$2:$E$240, LAMBDA(rEmisor,rPatron,rConcepto,rTipo, IF( AND( OR( UPPER(TRIM(rEmisor))=UPPER(TRIM(C15)), UPPER(TRIM(rEmisor))=""CUALQUIERA"" ), OR( UPPER(TRIM(rTipo))="&"""SOLO EMISOR"", AND( UPPER(TRIM(rTipo))=""EXACTA"", UPPER(TRIM(D15))=UPPER(TRIM(rPatron)) ), AND( OR( UPPER(TRIM(rTipo))=""CONTIENE"", UPPER(TRIM(rTipo))=""COINCIDENCIA"" ), ISNUMBER(SEARCH(UPPER(TRIM(rPatron)),UPPER(TRIM(D15)))) ) ) ), rConcepto, """" )"&" ) )<>"""" ), 1 ), """" )"),"OTRAS ASESORIAS") -> OTRAS ASESORIAS
B16: MXN | C16: BERTHA CORTES CORTES | D16: Servicio de Tráiler Caja 53 FT Eco 32-B realizado el día 02 de Agosto del 2026. Origen: AIFA Destino: Teoloyucan Referencia: IMILE02082026-ECO 32-B | E16: 11500 | F16: 0 | G16: IMILE AIFA | H16: {=INDEX(CC!C:C,MATCH(1,(CC!A:A=G16)*(CC!B:B=I16),0))} -> 1403 | I16: TERCEROS | J16: 11500 | K16: =IFERROR(__xludf.DUMMYFUNCTION("IFERROR( INDEX( FILTER( MAP( reglas!$B$2:$B$240, reglas!$C$2:$C$240, reglas!$D$2:$D$240, reglas!$E$2:$E$240, LAMBDA(rEmisor,rPatron,rConcepto,rTipo, IF( AND( OR( UPPER(TRIM(rEmisor))=UPPER(TRIM(C16)), UPPER(TRIM(rEmisor))=""CUALQUIERA"" ), OR( UPPER(TRIM("&"rTipo))=""SOLO EMISOR"", AND( UPPER(TRIM(rTipo))=""EXACTA"", UPPER(TRIM(AG16))=UPPER(TRIM(rPatron)) ), AND( OR( UPPER(TRIM(rTipo))=""CONTIENE"", UPPER(TRIM(rTipo))=""COINCIDENCIA"" ), ISNUMBER(SEARCH(UPPER(TRIM(rPatron)),UPPER(TRIM(D16)))) ) ) ), rConcept"&"o, """" ) ) ), MAP( reglas!$B$2:$B$240, reglas!$C$2:$C$240, reglas!$D$2:$D$240, reglas!$E$2:$E$240, LAMBDA(rEmisor,rPatron,rConcepto,rTipo, IF( AND( OR( UPPER(TRIM(rEmisor))=UPPER(TRIM(C16)), UPPER(TRIM(rEmisor))=""CUALQUIERA"" ), OR( UPPER(TRIM(rTipo))="&"""SOLO EMISOR"", AND( UPPER(TRIM(rTipo))=""EXACTA"", UPPER(TRIM(D16))=UPPER(TRIM(rPatron)) ), AND( OR( UPPER(TRIM(rTipo))=""CONTIENE"", UPPER(TRIM(rTipo))=""COINCIDENCIA"" ), ISNUMBER(SEARCH(UPPER(TRIM(rPatron)),UPPER(TRIM(D16)))) ) ) ), rConcepto, """" )"&" ) )<>"""" ), 1 ), """" )"),"TRANSPORTE") -> TRANSPORTE
B17: MXN | C17: JORGE ANGEL GOMEZ TERRAZAS | D17: Consultoria Gestión y Estrategia en Negocios | E17: 207500 | F17: 0 | G17: STAFF | H17: {=INDEX(CC!C:C,MATCH(1,(CC!A:A=G17)*(CC!B:B=I17),0))} -> 102 | I17: PROPIOS | J17: 207500 | K17: =IFERROR(__xludf.DUMMYFUNCTION("IFERROR( INDEX( FILTER( MAP( reglas!$B$2:$B$240, reglas!$C$2:$C$240, reglas!$D$2:$D$240, reglas!$E$2:$E$240, LAMBDA(rEmisor,rPatron,rConcepto,rTipo, IF( AND( OR( UPPER(TRIM(rEmisor))=UPPER(TRIM(C17)), UPPER(TRIM(rEmisor))=""CUALQUIERA"" ), OR( UPPER(TRIM("&"rTipo))=""SOLO EMISOR"", AND( UPPER(TRIM(rTipo))=""EXACTA"", UPPER(TRIM(AG17))=UPPER(TRIM(rPatron)) ), AND( OR( UPPER(TRIM(rTipo))=""CONTIENE"", UPPER(TRIM(rTipo))=""COINCIDENCIA"" ), ISNUMBER(SEARCH(UPPER(TRIM(rPatron)),UPPER(TRIM(D17)))) ) ) ), rConcept"&"o, """" ) ) ), MAP( reglas!$B$2:$B$240, reglas!$C$2:$C$240, reglas!$D$2:$D$240, reglas!$E$2:$E$240, LAMBDA(rEmisor,rPatron,rConcepto,rTipo, IF( AND( OR( UPPER(TRIM(rEmisor))=UPPER(TRIM(C17)), UPPER(TRIM(rEmisor))=""CUALQUIERA"" ), OR( UPPER(TRIM(rTipo))="&"""SOLO EMISOR"", AND( UPPER(TRIM(rTipo))=""EXACTA"", UPPER(TRIM(D17))=UPPER(TRIM(rPatron)) ), AND( OR( UPPER(TRIM(rTipo))=""CONTIENE"", UPPER(TRIM(rTipo))=""COINCIDENCIA"" ), ISNUMBER(SEARCH(UPPER(TRIM(rPatron)),UPPER(TRIM(D17)))) ) ) ), rConcepto, """" )"&" ) )<>"""" ), 1 ), """" )"),"OTRAS ASESORIAS") -> OTRAS ASESORIAS
B18: MXN | C18: CRISTOFER PAZ JIMENEZ | D18: FLETE LOCAL ADUANA AIFA A CUAUTITLÁN, EDO. MÉX. 02/08/2026. | E18: 11500 | F18: 0 | G18: IMILE AIFA | H18: {=INDEX(CC!C:C,MATCH(1,(CC!A:A=G18)*(CC!B:B=I18),0))} -> 1402 | I18: PROPIOS | J18: 11500 | K18: =IFERROR(__xludf.DUMMYFUNCTION("IFERROR( INDEX( FILTER( MAP( reglas!$B$2:$B$240, reglas!$C$2:$C$240, reglas!$D$2:$D$240, reglas!$E$2:$E$240, LAMBDA(rEmisor,rPatron,rConcepto,rTipo, IF( AND( OR( UPPER(TRIM(rEmisor))=UPPER(TRIM(C18)), UPPER(TRIM(rEmisor))=""CUALQUIERA"" ), OR( UPPER(TRIM("&"rTipo))=""SOLO EMISOR"", AND( UPPER(TRIM(rTipo))=""EXACTA"", UPPER(TRIM(AG18))=UPPER(TRIM(rPatron)) ), AND( OR( UPPER(TRIM(rTipo))=""CONTIENE"", UPPER(TRIM(rTipo))=""COINCIDENCIA"" ), ISNUMBER(SEARCH(UPPER(TRIM(rPatron)),UPPER(TRIM(D18)))) ) ) ), rConcept"&"o, """" ) ) ), MAP( reglas!$B$2:$B$240, reglas!$C$2:$C$240, reglas!$D$2:$D$240, reglas!$E$2:$E$240, LAMBDA(rEmisor,rPatron,rConcepto,rTipo, IF( AND( OR( UPPER(TRIM(rEmisor))=UPPER(TRIM(C18)), UPPER(TRIM(rEmisor))=""CUALQUIERA"" ), OR( UPPER(TRIM(rTipo))="&"""SOLO EMISOR"", AND( UPPER(TRIM(rTipo))=""EXACTA"", UPPER(TRIM(D18))=UPPER(TRIM(rPatron)) ), AND( OR( UPPER(TRIM(rTipo))=""CONTIENE"", UPPER(TRIM(rTipo))=""COINCIDENCIA"" ), ISNUMBER(SEARCH(UPPER(TRIM(rPatron)),UPPER(TRIM(D18)))) ) ) ), rConcepto, """" )"&" ) )<>"""" ), 1 ), """" )"),"TRANSPORTE") -> TRANSPORTE
A19: 1 | B19: MXN | C19: FEDERAL EXPRESS HOLDINGS (MEXICO) Y COMPAÑIA | D19: Etiquetado | E19: 600 | F19: 478 | G19: TOLUCA | H19: {=INDEX(CC!C:C,MATCH(1,(CC!A:A=G19)*(CC!B:B=I19),0))} -> 1002 | I19: PROPIOS | J19: 122 | K19: =IFERROR(__xludf.DUMMYFUNCTION("IFERROR( INDEX( FILTER( MAP( reglas!$B$2:$B$240, reglas!$C$2:$C$240, reglas!$D$2:$D$240, reglas!$E$2:$E$240, LAMBDA(rEmisor,rPatron,rConcepto,rTipo, IF( AND( OR( UPPER(TRIM(rEmisor))=UPPER(TRIM(C19)), UPPER(TRIM(rEmisor))=""CUALQUIERA"" ), OR( UPPER(TRIM("&"rTipo))=""SOLO EMISOR"", AND( UPPER(TRIM(rTipo))=""EXACTA"", UPPER(TRIM(AG19))=UPPER(TRIM(rPatron)) ), AND( OR( UPPER(TRIM(rTipo))=""CONTIENE"", UPPER(TRIM(rTipo))=""COINCIDENCIA"" ), ISNUMBER(SEARCH(UPPER(TRIM(rPatron)),UPPER(TRIM(D19)))) ) ) ), rConcept"&"o, """" ) ) ), MAP( reglas!$B$2:$B$240, reglas!$C$2:$C$240, reglas!$D$2:$D$240, reglas!$E$2:$E$240, LAMBDA(rEmisor,rPatron,rConcepto,rTipo, IF( AND( OR( UPPER(TRIM(rEmisor))=UPPER(TRIM(C19)), UPPER(TRIM(rEmisor))=""CUALQUIERA"" ), OR( UPPER(TRIM(rTipo))="&"""SOLO EMISOR"", AND( UPPER(TRIM(rTipo))=""EXACTA"", UPPER(TRIM(D19))=UPPER(TRIM(rPatron)) ), AND( OR( UPPER(TRIM(rTipo))=""CONTIENE"", UPPER(TRIM(rTipo))=""COINCIDENCIA"" ), ISNUMBER(SEARCH(UPPER(TRIM(rPatron)),UPPER(TRIM(D19)))) ) ) ), rConcepto, """" )"&" ) )<>"""" ), 1 ), """" )"),"MANIOBRAS") -> MANIOBRAS
C20: FEDERAL EXPRESS HOLDINGS (MEXICO) Y COMPAÑIA | D20: Cambio de Instruccion | E20: 634.54 | F20: 0 | G20: TOLUCA | H20: {=INDEX(CC!C:C,MATCH(1,(CC!A:A=G20)*(CC!B:B=I20),0))} -> 1002 | I20: PROPIOS | J20: 634.54 | K20: =IFERROR(__xludf.DUMMYFUNCTION("IFERROR( INDEX( FILTER( MAP( reglas!$B$2:$B$240, reglas!$C$2:$C$240, reglas!$D$2:$D$240, reglas!$E$2:$E$240, LAMBDA(rEmisor,rPatron,rConcepto,rTipo, IF( AND( OR( UPPER(TRIM(rEmisor))=UPPER(TRIM(C20)), UPPER(TRIM(rEmisor))=""CUALQUIERA"" ), OR( UPPER(TRIM("&"rTipo))=""SOLO EMISOR"", AND( UPPER(TRIM(rTipo))=""EXACTA"", UPPER(TRIM(AG20))=UPPER(TRIM(rPatron)) ), AND( OR( UPPER(TRIM(rTipo))=""CONTIENE"", UPPER(TRIM(rTipo))=""COINCIDENCIA"" ), ISNUMBER(SEARCH(UPPER(TRIM(rPatron)),UPPER(TRIM(D20)))) ) ) ), rConcept"&"o, """" ) ) ), MAP( reglas!$B$2:$B$240, reglas!$C$2:$C$240, reglas!$D$2:$D$240, reglas!$E$2:$E$240, LAMBDA(rEmisor,rPatron,rConcepto,rTipo, IF( AND( OR( UPPER(TRIM(rEmisor))=UPPER(TRIM(C20)), UPPER(TRIM(rEmisor))=""CUALQUIERA"" ), OR( UPPER(TRIM(rTipo))="&"""SOLO EMISOR"", AND( UPPER(TRIM(rTipo))=""EXACTA"", UPPER(TRIM(D20))=UPPER(TRIM(rPatron)) ), AND( OR( UPPER(TRIM(rTipo))=""CONTIENE"", UPPER(TRIM(rTipo))=""COINCIDENCIA"" ), ISNUMBER(SEARCH(UPPER(TRIM(rPatron)),UPPER(TRIM(D20)))) ) ) ), rConcepto, """" )"&" ) )<>"""" ), 1 ), """" )"),"MANIOBRAS") -> MANIOBRAS
C21: FEDERAL EXPRESS HOLDINGS (MEXICO) Y COMPAÑIA | D21: Almacenaje | E21: 634.89 | F21: 0 | G21: TOLUCA | H21: {=INDEX(CC!C:C,MATCH(1,(CC!A:A=G21)*(CC!B:B=I21),0))} -> 1002 | I21: PROPIOS | J21: 634.89 | K21: =IFERROR(__xludf.DUMMYFUNCTION("IFERROR( INDEX( FILTER( MAP( reglas!$B$2:$B$240, reglas!$C$2:$C$240, reglas!$D$2:$D$240, reglas!$E$2:$E$240, LAMBDA(rEmisor,rPatron,rConcepto,rTipo, IF( AND( OR( UPPER(TRIM(rEmisor))=UPPER(TRIM(C21)), UPPER(TRIM(rEmisor))=""CUALQUIERA"" ), OR( UPPER(TRIM("&"rTipo))=""SOLO EMISOR"", AND( UPPER(TRIM(rTipo))=""EXACTA"", UPPER(TRIM(AG21))=UPPER(TRIM(rPatron)) ), AND( OR( UPPER(TRIM(rTipo))=""CONTIENE"", UPPER(TRIM(rTipo))=""COINCIDENCIA"" ), ISNUMBER(SEARCH(UPPER(TRIM(rPatron)),UPPER(TRIM(D21)))) ) ) ), rConcept"&"o, """" ) ) ), MAP( reglas!$B$2:$B$240, reglas!$C$2:$C$240, reglas!$D$2:$D$240, reglas!$E$2:$E$240, LAMBDA(rEmisor,rPatron,rConcepto,rTipo, IF( AND( OR( UPPER(TRIM(rEmisor))=UPPER(TRIM(C21)), UPPER(TRIM(rEmisor))=""CUALQUIERA"" ), OR( UPPER(TRIM(rTipo))="&"""SOLO EMISOR"", AND( UPPER(TRIM(rTipo))=""EXACTA"", UPPER(TRIM(D21))=UPPER(TRIM(rPatron)) ), AND( OR( UPPER(TRIM(rTipo))=""CONTIENE"", UPPER(TRIM(rTipo))=""COINCIDENCIA"" ), ISNUMBER(SEARCH(UPPER(TRIM(rPatron)),UPPER(TRIM(D21)))) ) ) ), rConcepto, """" )"&" ) )<>"""" ), 1 ), """" )"),"MANIOBRAS") -> MANIOBRAS
C22: FEDERAL EXPRESS HOLDINGS (MEXICO) Y COMPAÑIA | D22: Asignacion de Guia Aerea | E22: 580.56 | F22: 0 | G22: TOLUCA | H22: {=INDEX(CC!C:C,MATCH(1,(CC!A:A=G22)*(CC!B:B=I22),0))} -> 1002 | I22: PROPIOS | J22: 580.56 | K22: =IFERROR(__xludf.DUMMYFUNCTION("IFERROR( INDEX( FILTER( MAP( reglas!$B$2:$B$240, reglas!$C$2:$C$240, reglas!$D$2:$D$240, reglas!$E$2:$E$240, LAMBDA(rEmisor,rPatron,rConcepto,rTipo, IF( AND( OR( UPPER(TRIM(rEmisor))=UPPER(TRIM(C22)), UPPER(TRIM(rEmisor))=""CUALQUIERA"" ), OR( UPPER(TRIM("&"rTipo))=""SOLO EMISOR"", AND( UPPER(TRIM(rTipo))=""EXACTA"", UPPER(TRIM(AG22))=UPPER(TRIM(rPatron)) ), AND( OR( UPPER(TRIM(rTipo))=""CONTIENE"", UPPER(TRIM(rTipo))=""COINCIDENCIA"" ), ISNUMBER(SEARCH(UPPER(TRIM(rPatron)),UPPER(TRIM(D22)))) ) ) ), rConcept"&"o, """" ) ) ), MAP( reglas!$B$2:$B$240, reglas!$C$2:$C$240, reglas!$D$2:$D$240, reglas!$E$2:$E$240, LAMBDA(rEmisor,rPatron,rConcepto,rTipo, IF( AND( OR( UPPER(TRIM(rEmisor))=UPPER(TRIM(C22)), UPPER(TRIM(rEmisor))=""CUALQUIERA"" ), OR( UPPER(TRIM(rTipo))="&"""SOLO EMISOR"", AND( UPPER(TRIM(rTipo))=""EXACTA"", UPPER(TRIM(D22))=UPPER(TRIM(rPatron)) ), AND( OR( UPPER(TRIM(rTipo))=""CONTIENE"", UPPER(TRIM(rTipo))=""COINCIDENCIA"" ), ISNUMBER(SEARCH(UPPER(TRIM(rPatron)),UPPER(TRIM(D22)))) ) ) ), rConcepto, """" )"&" ) )<>"""" ), 1 ), """" )"),"MANIOBRAS") -> MANIOBRAS
C23: FEDERAL EXPRESS HOLDINGS (MEXICO) Y COMPAÑIA | D23: Manejo | E23: 634.89 | F23: 0 | G23: TOLUCA | H23: {=INDEX(CC!C:C,MATCH(1,(CC!A:A=G23)*(CC!B:B=I23),0))} -> 1002 | I23: PROPIOS | J23: 634.89 | K23: =IFERROR(__xludf.DUMMYFUNCTION("IFERROR( INDEX( FILTER( MAP( reglas!$B$2:$B$240, reglas!$C$2:$C$240, reglas!$D$2:$D$240, reglas!$E$2:$E$240, LAMBDA(rEmisor,rPatron,rConcepto,rTipo, IF( AND( OR( UPPER(TRIM(rEmisor))=UPPER(TRIM(C23)), UPPER(TRIM(rEmisor))=""CUALQUIERA"" ), OR( UPPER(TRIM("&"rTipo))=""SOLO EMISOR"", AND( UPPER(TRIM(rTipo))=""EXACTA"", UPPER(TRIM(AG23))=UPPER(TRIM(rPatron)) ), AND( OR( UPPER(TRIM(rTipo))=""CONTIENE"", UPPER(TRIM(rTipo))=""COINCIDENCIA"" ), ISNUMBER(SEARCH(UPPER(TRIM(rPatron)),UPPER(TRIM(D23)))) ) ) ), rConcept"&"o, """" ) ) ), MAP( reglas!$B$2:$B$240, reglas!$C$2:$C$240, reglas!$D$2:$D$240, reglas!$E$2:$E$240, LAMBDA(rEmisor,rPatron,rConcepto,rTipo, IF( AND( OR( UPPER(TRIM(rEmisor))=UPPER(TRIM(C23)), UPPER(TRIM(rEmisor))=""CUALQUIERA"" ), OR( UPPER(TRIM(rTipo))="&"""SOLO EMISOR"", AND( UPPER(TRIM(rTipo))=""EXACTA"", UPPER(TRIM(D23))=UPPER(TRIM(rPatron)) ), AND( OR( UPPER(TRIM(rTipo))=""CONTIENE"", UPPER(TRIM(rTipo))=""COINCIDENCIA"" ), ISNUMBER(SEARCH(UPPER(TRIM(rPatron)),UPPER(TRIM(D23)))) ) ) ), rConcepto, """" )"&" ) )<>"""" ), 1 ), """" )"),"MANIOBRAS") -> MANIOBRAS
C24: FEDERAL EXPRESS HOLDINGS (MEXICO) Y COMPAÑIA | D24: Custodia | E24: 360.49 | F24: 0 | G24: TOLUCA | H24: {=INDEX(CC!C:C,MATCH(1,(CC!A:A=G24)*(CC!B:B=I24),0))} -> 1002 | I24: PROPIOS | J24: 360.49 | K24: =IFERROR(__xludf.DUMMYFUNCTION("IFERROR( INDEX( FILTER( MAP( reglas!$B$2:$B$240, reglas!$C$2:$C$240, reglas!$D$2:$D$240, reglas!$E$2:$E$240, LAMBDA(rEmisor,rPatron,rConcepto,rTipo, IF( AND( OR( UPPER(TRIM(rEmisor))=UPPER(TRIM(C24)), UPPER(TRIM(rEmisor))=""CUALQUIERA"" ), OR( UPPER(TRIM("&"rTipo))=""SOLO EMISOR"", AND( UPPER(TRIM(rTipo))=""EXACTA"", UPPER(TRIM(AG24))=UPPER(TRIM(rPatron)) ), AND( OR( UPPER(TRIM(rTipo))=""CONTIENE"", UPPER(TRIM(rTipo))=""COINCIDENCIA"" ), ISNUMBER(SEARCH(UPPER(TRIM(rPatron)),UPPER(TRIM(D24)))) ) ) ), rConcept"&"o, """" ) ) ), MAP( reglas!$B$2:$B$240, reglas!$C$2:$C$240, reglas!$D$2:$D$240, reglas!$E$2:$E$240, LAMBDA(rEmisor,rPatron,rConcepto,rTipo, IF( AND( OR( UPPER(TRIM(rEmisor))=UPPER(TRIM(C24)), UPPER(TRIM(rEmisor))=""CUALQUIERA"" ), OR( UPPER(TRIM(rTipo))="&"""SOLO EMISOR"", AND( UPPER(TRIM(rTipo))=""EXACTA"", UPPER(TRIM(D24))=UPPER(TRIM(rPatron)) ), AND( OR( UPPER(TRIM(rTipo))=""CONTIENE"", UPPER(TRIM(rTipo))=""COINCIDENCIA"" ), ISNUMBER(SEARCH(UPPER(TRIM(rPatron)),UPPER(TRIM(D24)))) ) ) ), rConcepto, """" )"&" ) )<>"""" ), 1 ), """" )"),"MANIOBRAS") -> MANIOBRAS
C25: FEDERAL EXPRESS HOLDINGS (MEXICO) Y COMPAÑIA | D25: Maniobras para Previo | E25: 666.13 | F25: 0 | G25: TOLUCA | H25: {=INDEX(CC!C:C,MATCH(1,(CC!A:A=G25)*(CC!B:B=I25),0))} -> 1002 | I25: PROPIOS | J25: 666.13 | K25: =IFERROR(__xludf.DUMMYFUNCTION("IFERROR( INDEX( FILTER( MAP( reglas!$B$2:$B$240, reglas!$C$2:$C$240, reglas!$D$2:$D$240, reglas!$E$2:$E$240, LAMBDA(rEmisor,rPatron,rConcepto,rTipo, IF( AND( OR( UPPER(TRIM(rEmisor))=UPPER(TRIM(C25)), UPPER(TRIM(rEmisor))=""CUALQUIERA"" ), OR( UPPER(TRIM("&"rTipo))=""SOLO EMISOR"", AND( UPPER(TRIM(rTipo))=""EXACTA"", UPPER(TRIM(AG25))=UPPER(TRIM(rPatron)) ), AND( OR( UPPER(TRIM(rTipo))=""CONTIENE"", UPPER(TRIM(rTipo))=""COINCIDENCIA"" ), ISNUMBER(SEARCH(UPPER(TRIM(rPatron)),UPPER(TRIM(D25)))) ) ) ), rConcept"&"o, """" ) ) ), MAP( reglas!$B$2:$B$240, reglas!$C$2:$C$240, reglas!$D$2:$D$240, reglas!$E$2:$E$240, LAMBDA(rEmisor,rPatron,rConcepto,rTipo, IF( AND( OR( UPPER(TRIM(rEmisor))=UPPER(TRIM(C25)), UPPER(TRIM(rEmisor))=""CUALQUIERA"" ), OR( UPPER(TRIM(rTipo))="&"""SOLO EMISOR"", AND( UPPER(TRIM(rTipo))=""EXACTA"", UPPER(TRIM(D25))=UPPER(TRIM(rPatron)) ), AND( OR( UPPER(TRIM(rTipo))=""CONTIENE"", UPPER(TRIM(rTipo))=""COINCIDENCIA"" ), ISNUMBER(SEARCH(UPPER(TRIM(rPatron)),UPPER(TRIM(D25)))) ) ) ), rConcepto, """" )"&" ) )<>"""" ), 1 ), """" )"),"MANIOBRAS") -> MANIOBRAS
B26: MXN | C26: SISTEMA UNIFICADO DE MANIOBRAS AEREAS PARA AGENTES ADUANALES | D26: Carga de camión | E26: 3500 | F26: 0 | G26: IMILE AIFA | H26: {=INDEX(CC!C:C,MATCH(1,(CC!A:A=G26)*(CC!B:B=I26),0))} -> 1402 | I26: PROPIOS | J26: 3500 | K26: =IFERROR(__xludf.DUMMYFUNCTION("IFERROR( INDEX( FILTER( MAP( reglas!$B$2:$B$240, reglas!$C$2:$C$240, reglas!$D$2:$D$240, reglas!$E$2:$E$240, LAMBDA(rEmisor,rPatron,rConcepto,rTipo, IF( AND( OR( UPPER(TRIM(rEmisor))=UPPER(TRIM(C26)), UPPER(TRIM(rEmisor))=""CUALQUIERA"" ), OR( UPPER(TRIM("&"rTipo))=""SOLO EMISOR"", AND( UPPER(TRIM(rTipo))=""EXACTA"", UPPER(TRIM(AG26))=UPPER(TRIM(rPatron)) ), AND( OR( UPPER(TRIM(rTipo))=""CONTIENE"", UPPER(TRIM(rTipo))=""COINCIDENCIA"" ), ISNUMBER(SEARCH(UPPER(TRIM(rPatron)),UPPER(TRIM(D26)))) ) ) ), rConcept"&"o, """" ) ) ), MAP( reglas!$B$2:$B$240, reglas!$C$2:$C$240, reglas!$D$2:$D$240, reglas!$E$2:$E$240, LAMBDA(rEmisor,rPatron,rConcepto,rTipo, IF( AND( OR( UPPER(TRIM(rEmisor))=UPPER(TRIM(C26)), UPPER(TRIM(rEmisor))=""CUALQUIERA"" ), OR( UPPER(TRIM(rTipo))="&"""SOLO EMISOR"", AND( UPPER(TRIM(rTipo))=""EXACTA"", UPPER(TRIM(D26))=UPPER(TRIM(rPatron)) ), AND( OR( UPPER(TRIM(rTipo))=""CONTIENE"", UPPER(TRIM(rTipo))=""COINCIDENCIA"" ), ISNUMBER(SEARCH(UPPER(TRIM(rPatron)),UPPER(TRIM(D26)))) ) ) ), rConcepto, """" )"&" ) )<>"""" ), 1 ), """" )"),"MANIOBRAS") -> MANIOBRAS
B27: MXN | C27: KYA TI | D27: Servicios de comercio internacional | E27: 20000 | F27: 0 | G27: LAREDO | H27: {=INDEX(CC!C:C,MATCH(1,(CC!A:A=G27)*(CC!B:B=I27),0))} -> 1302 | I27: PROPIOS | K27: =IFERROR(__xludf.DUMMYFUNCTION("IFERROR( INDEX( FILTER( MAP( reglas!$B$2:$B$240, reglas!$C$2:$C$240, reglas!$D$2:$D$240, reglas!$E$2:$E$240, LAMBDA(rEmisor,rPatron,rConcepto,rTipo, IF( AND( OR( UPPER(TRIM(rEmisor))=UPPER(TRIM(C27)), UPPER(TRIM(rEmisor))=""CUALQUIERA"" ), OR( UPPER(TRIM("&"rTipo))=""SOLO EMISOR"", AND( UPPER(TRIM(rTipo))=""EXACTA"", UPPER(TRIM(AG27))=UPPER(TRIM(rPatron)) ), AND( OR( UPPER(TRIM(rTipo))=""CONTIENE"", UPPER(TRIM(rTipo))=""COINCIDENCIA"" ), ISNUMBER(SEARCH(UPPER(TRIM(rPatron)),UPPER(TRIM(D27)))) ) ) ), rConcept"&"o, """" ) ) ), MAP( reglas!$B$2:$B$240, reglas!$C$2:$C$240, reglas!$D$2:$D$240, reglas!$E$2:$E$240, LAMBDA(rEmisor,rPatron,rConcepto,rTipo, IF( AND( OR( UPPER(TRIM(rEmisor))=UPPER(TRIM(C27)), UPPER(TRIM(rEmisor))=""CUALQUIERA"" ), OR( UPPER(TRIM(rTipo))="&"""SOLO EMISOR"", AND( UPPER(TRIM(rTipo))=""EXACTA"", UPPER(TRIM(D27))=UPPER(TRIM(rPatron)) ), AND( OR( UPPER(TRIM(rTipo))=""CONTIENE"", UPPER(TRIM(rTipo))=""COINCIDENCIA"" ), ISNUMBER(SEARCH(UPPER(TRIM(rPatron)),UPPER(TRIM(D27)))) ) ) ), rConcepto, """" )"&" ) )<>"""" ), 1 ), """" )"),"VALIDACION") -> VALIDACION
C28: KYA TI | D28: Servicios de comercio internacional | G28: ESTAFETA | H28: {=INDEX(CC!C:C,MATCH(1,(CC!A:A=G28)*(CC!B:B=I28),0))} -> 402 | I28: PROPIOS | K28: =IFERROR(__xludf.DUMMYFUNCTION("IFERROR( INDEX( FILTER( MAP( reglas!$B$2:$B$240, reglas!$C$2:$C$240, reglas!$D$2:$D$240, reglas!$E$2:$E$240, LAMBDA(rEmisor,rPatron,rConcepto,rTipo, IF( AND( OR( UPPER(TRIM(rEmisor))=UPPER(TRIM(C28)), UPPER(TRIM(rEmisor))=""CUALQUIERA"" ), OR( UPPER(TRIM("&"rTipo))=""SOLO EMISOR"", AND( UPPER(TRIM(rTipo))=""EXACTA"", UPPER(TRIM(AG28))=UPPER(TRIM(rPatron)) ), AND( OR( UPPER(TRIM(rTipo))=""CONTIENE"", UPPER(TRIM(rTipo))=""COINCIDENCIA"" ), ISNUMBER(SEARCH(UPPER(TRIM(rPatron)),UPPER(TRIM(D28)))) ) ) ), rConcept"&"o, """" ) ) ), MAP( reglas!$B$2:$B$240, reglas!$C$2:$C$240, reglas!$D$2:$D$240, reglas!$E$2:$E$240, LAMBDA(rEmisor,rPatron,rConcepto,rTipo, IF( AND( OR( UPPER(TRIM(rEmisor))=UPPER(TRIM(C28)), UPPER(TRIM(rEmisor))=""CUALQUIERA"" ), OR( UPPER(TRIM(rTipo))="&"""SOLO EMISOR"", AND( UPPER(TRIM(rTipo))=""EXACTA"", UPPER(TRIM(D28))=UPPER(TRIM(rPatron)) ), AND( OR( UPPER(TRIM(rTipo))=""CONTIENE"", UPPER(TRIM(rTipo))=""COINCIDENCIA"" ), ISNUMBER(SEARCH(UPPER(TRIM(rPatron)),UPPER(TRIM(D28)))) ) ) ), rConcepto, """" )"&" ) )<>"""" ), 1 ), """" )"),"VALIDACION") -> VALIDACION
C29: KYA TI | D29: Servicios de comercio internacional | G29: MANZANILLO | H29: {=INDEX(CC!C:C,MATCH(1,(CC!A:A=G29)*(CC!B:B=I29),0))} -> 1202 | I29: PROPIOS | K29: =IFERROR(__xludf.DUMMYFUNCTION("IFERROR( INDEX( FILTER( MAP( reglas!$B$2:$B$240, reglas!$C$2:$C$240, reglas!$D$2:$D$240, reglas!$E$2:$E$240, LAMBDA(rEmisor,rPatron,rConcepto,rTipo, IF( AND( OR( UPPER(TRIM(rEmisor))=UPPER(TRIM(C29)), UPPER(TRIM(rEmisor))=""CUALQUIERA"" ), OR( UPPER(TRIM("&"rTipo))=""SOLO EMISOR"", AND( UPPER(TRIM(rTipo))=""EXACTA"", UPPER(TRIM(AG29))=UPPER(TRIM(rPatron)) ), AND( OR( UPPER(TRIM(rTipo))=""CONTIENE"", UPPER(TRIM(rTipo))=""COINCIDENCIA"" ), ISNUMBER(SEARCH(UPPER(TRIM(rPatron)),UPPER(TRIM(D29)))) ) ) ), rConcept"&"o, """" ) ) ), MAP( reglas!$B$2:$B$240, reglas!$C$2:$C$240, reglas!$D$2:$D$240, reglas!$E$2:$E$240, LAMBDA(rEmisor,rPatron,rConcepto,rTipo, IF( AND( OR( UPPER(TRIM(rEmisor))=UPPER(TRIM(C29)), UPPER(TRIM(rEmisor))=""CUALQUIERA"" ), OR( UPPER(TRIM(rTipo))="&"""SOLO EMISOR"", AND( UPPER(TRIM(rTipo))=""EXACTA"", UPPER(TRIM(D29))=UPPER(TRIM(rPatron)) ), AND( OR( UPPER(TRIM(rTipo))=""CONTIENE"", UPPER(TRIM(rTipo))=""COINCIDENCIA"" ), ISNUMBER(SEARCH(UPPER(TRIM(rPatron)),UPPER(TRIM(D29)))) ) ) ), rConcepto, """" )"&" ) )<>"""" ), 1 ), """" )"),"VALIDACION") -> VALIDACION
B30: MXN | C30: CRISTOFER PAZ JIMENEZ | D30: FLETE LOCAL ADUANA AIFA A CUAUTITLÁN, EDO. MÉX. 03/08/2026. | E30: 11500 | F30: 0 | G30: IMILE AIFA | H30: {=INDEX(CC!C:C,MATCH(1,(CC!A:A=G30)*(CC!B:B=I30),0))} -> 1402 | I30: PROPIOS | J30: 11500 | K30: =IFERROR(__xludf.DUMMYFUNCTION("IFERROR( INDEX( FILTER( MAP( reglas!$B$2:$B$240, reglas!$C$2:$C$240, reglas!$D$2:$D$240, reglas!$E$2:$E$240, LAMBDA(rEmisor,rPatron,rConcepto,rTipo, IF( AND( OR( UPPER(TRIM(rEmisor))=UPPER(TRIM(C30)), UPPER(TRIM(rEmisor))=""CUALQUIERA"" ), OR( UPPER(TRIM("&"rTipo))=""SOLO EMISOR"", AND( UPPER(TRIM(rTipo))=""EXACTA"", UPPER(TRIM(AG30))=UPPER(TRIM(rPatron)) ), AND( OR( UPPER(TRIM(rTipo))=""CONTIENE"", UPPER(TRIM(rTipo))=""COINCIDENCIA"" ), ISNUMBER(SEARCH(UPPER(TRIM(rPatron)),UPPER(TRIM(D30)))) ) ) ), rConcept"&"o, """" ) ) ), MAP( reglas!$B$2:$B$240, reglas!$C$2:$C$240, reglas!$D$2:$D$240, reglas!$E$2:$E$240, LAMBDA(rEmisor,rPatron,rConcepto,rTipo, IF( AND( OR( UPPER(TRIM(rEmisor))=UPPER(TRIM(C30)), UPPER(TRIM(rEmisor))=""CUALQUIERA"" ), OR( UPPER(TRIM(rTipo))="&"""SOLO EMISOR"", AND( UPPER(TRIM(rTipo))=""EXACTA"", UPPER(TRIM(D30))=UPPER(TRIM(rPatron)) ), AND( OR( UPPER(TRIM(rTipo))=""CONTIENE"", UPPER(TRIM(rTipo))=""COINCIDENCIA"" ), ISNUMBER(SEARCH(UPPER(TRIM(rPatron)),UPPER(TRIM(D30)))) ) ) ), rConcepto, """" )"&" ) )<>"""" ), 1 ), """" )"),"TRANSPORTE") -> TRANSPORTE
